Workbook

Sheet bitacoras enero I
B1: CONTROL DE BITACORAS | D1: RECORRIDO KILOMETRAJE 2-DICIEMBRE -2025 | I1: RECORRIDO KILOMETRAJE ENERO (1) -2026 | N1: RECORRIDO KILOMETRAJE ENERO (2) -2026 | S1: RECORRIDO KILOMETRAJE FEBRERO (1) -2026 | X1: RECORRIDO KILOMETRAJE FEBRERO (2) -2026 | AC1: RECORRIDO KILOMETRAJE MARZO (1) -2026 | AH1: RECORRIDO KILOMETRAJE MARZO (2) -2026 | AM1: RECORRIDO KILOMETRAJE ABRIL (1) -2026
B2: Nombre del conductor | C2: Marca y N° de Placa | D2: INICIO | E2: FINAL | F2: KILOMETRO RECORRIDO | G2: PROMEDIO | H2: SALDO COMBUST. | I2: INICIO | J2: FINAL | K2: KILOMETRO RECORRIDO | L2: PROMEDIO | M2: SALDO COMBUST. | N2: INICIO | O2: FINAL | P2: KILOMETRO RECORRIDO | Q2: PROMEDIO | R2: SALDO COMBUST. | S2: INICIO | T2: FINAL | U2: KILOMETRO RECORRIDO | V2: PROMEDIO | W2: SALDO COMBUST. | X2: INICIO | Y2: FINAL | Z2: KILOMETRO RECORRIDO | AA2: PROMEDIO | AB2: SALDO COMBUST. | AC2: INICIO | AD2: FINAL | AE2: KILOMETRO RECORRIDO | AF2: PROMEDIO | AG2: SALDO COMBUST. | AH2: INICIO | AI2: FINAL | AJ2: KILOMETRO RECORRIDO | AK2: PROMEDIO | AL2: SALDO COMBUST. | AM2: INICIO | AN2: FINAL | AO2: KILOMETRO RECORRIDO | AP2: PROMEDIO | AQ2: SALDO COMBUST.
A3: 1 | B3: ALDO ALMAZAN TRONCOSO | C3: TOYOTA 3027 SXC | D3: 351900 | E3: 352201 | F3: 301 | G3: 5.308642 | H3: 179 | I3: =+E3 -> 352201 | J3: 352500 | K3: =+J3-I3 -> 299 | L3: =+K3/(179+10+20-159.2) -> 6.0040161 | M3: 159.2 | N3: =+J3 -> 352500 | O3: 352910 | P3: =+O3-N3 -> 410 | Q3: =+P3/(M3+28.74+74-R3) -> 5.9994147 | R3: 193.6 | S3: =+O3 -> 352910 | T3: 353098 | U3: =+T3-S3 -> 188 | V3: =+U3/(R3+77.85-W3) -> 5.9968102 | W3: 240.1 | X3: =+T3 -> 353098 | Y3: 353773 | Z3: =+Y3-X3 -> 675 | AA3: =+Z3/(W3-AB3) -> 5 | AB3: 105.1 | AC3: =+Y3 -> 353773 | AD3: 354346 | AE3: =+AD3-AC3 -> 573 | AF3: =+AE3/(AB3+14-AG3) -> 6 | AG3: 23.6 | AH3: =+AD3 -> 354346 | AI3: 354722 | AJ3: =+AI3-AH3 -> 376 | AK3: =+AJ3/(AG3+68+75-AL3) -> 5.9968102 | AL3: 103.9 | AM3: =+AI3 -> 354722 | AN3: 354722 | AO3: =+AN3-AM3 -> 0 | AP3: =+AO3/(AL3+68+75-AQ3) -> 0 | AQ3: 103.9
A4: =+A3+1 -> 2 | B4: ARMANDO QUISPE CORONADO | C4: COMPRESOR 4606 GAD | D4: SIN MOVIMIENTO | G4: 0 | H4: 201 | I4: SIN MOVIMIENTO | L4: =+K4/(24+268-201) -> 0 | N4: SIN MOVIMIENTO | O4: 43720 | Q4: =+P4/(24+268-201) -> 0 | R4: 201 | S4: =+O4 -> 43720 | T4: 43730 | U4: =+T4-S4 -> 10 | V4: =+U4/(R4+157-W4) -> 2 | W4: 353 | X4: =+T4 -> 43730 | Y4: SIN MOVIMIENTO | Z4: =+Y4-X4 -> #VALUE! | AA4: =+Z4/(W4+157-AB4) -> #VALUE! | AB4: 353 | AC4: 43730 | AD4: 43820 | AE4: =+AD4-AC4 -> 90 | AF4: =+AE4/(AB4+170-AG4) -> 1.0465116 | AG4: 437 | AH4: 43820 | AI4: 43820 | AJ4: SIN MOVIMIENTO | AK4: =+AJ4/(AG4-AL4) -> #VALUE! | AL4: 437 | AM4: 43820 | AN4: 43908 | AO4: =+AN4-AM4 -> 88 | AP4: =+AO4/(AL4-AQ4) -> 2 | AQ4: 393
A5: =+A4+1 -> 3 | B5: AUSBERTO SOTO MAMANI | C5: TOYOTA 4829 RLA | D5: 267576 | E5: 268475 | F5: 899 | G5: 6.4013102 | H5: 17.28 | I5: =+E5 -> 268475 | J5: 269884 | K5: =+J5-I5 -> 1409 | L5: =+K5/(17.28+60+100-17.28) -> 8.80625 | M5: 17.28 | N5: =+J5 -> 269884 | O5: 271672 | P5: =+O5-N5 -> 1788 | Q5: =+P5/(M5+28.74+71.23+76+64-R5) -> 7.3680307 | R5: 14.58 | S5: =+O5 -> 271672 | T5: 272870 | U5: =+T5-S5 -> 1198 | V5: =+U5/(R5+10+154.6+10+68.86-W5) -> 6.4019665 | W5: 70.91 | X5: =+T5 -> 272870 | Y5: 275450 | Z5: =+Y5-X5 -> 2580 | AA5: =+Z5/(W5+77.5+128.12+138-AB5) -> 6.4002381 | AB5: 11.42 | AC5: =+Y5 -> 275450 | AD5: 278115 | AE5: =+AD5-AC5 -> 2665 | AF5: =+AE5/(AB5+79+69+141.34+123-AG5) -> 6.4007109 | AG5: 7.4 | AH5: =+AD5 -> 278115 | AI5: 279218 | AJ5: =+AI5-AH5 -> 1103 | AK5: =+AJ5/(AG5+30+144.72-AL5) -> 6.4012536 | AL5: 9.81 | AM5: =+AI5 -> 279218 | AN5: 281250 | AO5: =+AN5-AM5 -> 2032 | AP5: =+AO5/(AL5+123+79+51.8+30-AQ5) -> 7.3233142 | AQ5: 16.14
A6: =+A5+1 -> 4 | B6: CELSO GALVAN POVEDA | C6: TOYOTA 4028 CGD | D6: 365218 | E6: 366120 | F6: 902 | G6: 3.9047619 | H6: 55 | I6: SIN MOVIMIENTO | J6: 366120 | K6: =+J6-I6 -> #VALUE! | L6: =+K6/(146+140-55) -> #VALUE! | M6: 55 | N6: =+J6 -> 366120 | O6: 366260 | P6: =+O6-N6 -> 140 | Q6: =+P6/(M6-R6) -> 4 | R6: 20 | S6: =+O6 -> 366260 | T6: 366840 | U6: =+T6-S6 -> 580 | V6: =+U6/(R6+80+120-W6) -> 3.8926174 | W6: 71 | X6: =+T6 -> 366840 | Y6: 367508 | Z6: =+Y6-X6 -> 668 | AA6: =+Z6/(W6+100+70-AB6) -> 3.8837209 | AB6: 69 | AC6: =+Y6 -> 367508 | AD6: 368850 | AE6: =+AD6-AC6 -> 1342 | AF6: =+AE6/(AB6+80+90+94-AG6) -> 4.2201258 | AG6: 15 | AH6: =+AD6 -> 368850 | AI6: 369585 | AJ6: =+AI6-AH6 -> 735 | AK6: =+AJ6/(AG6+114+100-AL6) -> 3.8684211 | AL6: 39 | AM6: =+AI6 -> 369585 | AN6: 370340 | AO6: =+AN6-AM6 -> 755 | AP6: =+AO6/(AL6+110+118-AQ6) -> 3.8917526 | AQ6: 73
A7: =+A6+1 -> 5 | B7: CELSO GALVAN POVEDA | C7: CAMION CISTERNA GAD 4608 | F7: 10 | G7: 0.03257329 | H7: 775 | I7: SIN MOVIMIENTO | K7: 10 | L7: =+K7/(604+478-775) -> 0.03257329 | N7: SIN MOVIMIENTO | P7: 10 | Q7: =+P7/(604+478-775) -> 0.03257329 | R7: 1190 | S7: SIN MOVIMIENTO | U7: 10 | V7: =+U7/(R7-W7) -> #DIV/0! | W7: 1190 | X7: SIN MOVIMIENTO | Z7: 10 | AA7: =+Z7/(W7-AB7) -> #DIV/0! | AB7: 1190 | AC7: SIN MOVIMIENTO | AE7: 10 | AF7: =+AE7/(AB7-AG7) -> #DIV/0! | AG7: 1190 | AH7: SIN MOVIMIENTO | AJ7: 10 | AK7: =+AJ7/(AG7-AL7) -> 0.1 | AL7: 1090 | AM7: SIN MOVIMIENTO | AO7: 0 | AP7: =+AO7/(AL7-AQ7) -> #DIV/0! | AQ7: 1090
A8: =+A7+1 -> 6 | B8: CELSO GALVAN POVEDA | C8: SINOTRUCK PERFORADOR 6448 IUS | F8: 187 | G8: 0.17093236 | H8: 189 | I8: SIN MOVIMIENTO | K8: 187 | L8: =+K8/(983+300-189) -> 0.17093236 | N8: SIN MOVIMIENTO | P8: 187 | Q8: =+P8/(983+300-189) -> 0.17093236 | R8: 89 | S8: SIN MOVIMIENTO | U8: 187 | V8: =+U8/(R8-W8) -> #DIV/0! | W8: 89 | X8: 3671 | Y8: 3757 | Z8: =+Y8-X8 -> 86 | AA8: =+Z8/(W8+750-AB8) -> 0.19815668 | AB8: 405 | AC8: =+Y8 -> 3757 | AD8: 3831 | AE8: =+AD8-AC8 -> 74 | AF8: =+AE8/(AB8-AG8) -> 0.26241135 | AG8: 123 | AH8: =+AD8 -> 3831 | AI8: 4025 | AJ8: =+AI8-AH8 -> 194 | AK8: =+AJ8/(AG8+744+100-AL8) -> 0.22045455 | AL8: 87 | AM8: =+AI8 -> 4025 | AN8: 4110 | AO8: =+AN8-AM8 -> 85 | AP8: =+AO8/(AL8+750-AQ8) -> 0.3024911 | AQ8: 556
A9: =+A8+1 -> 7 | B9: DANIEL MAMANI CHOQUE | C9: TOYOTA 2980 XPC | D9: 462002 | E9: 463577 | F9: 1575 | G9: 6.6046044 | H9: 117 | I9: =+E9 -> 463577 | J9: 464115 | K9: =+J9-I9 -> 538 | L9: =+K9/(62.43+30+30-32.8) -> 6.0024545 | M9: 32.8 | N9: =+J9 -> 464115 | O9: 464283 | P9: =+O9-N9 -> 168 | Q9: =+P9/(M9+28-R9) -> 5.5390702 | R9: 30.47
A10: =+A9+1 -> 8 | B10: DANIEL MAMANI CHOQUE | C10: TOYOTA 4829 RYF | N10: CAMBIO DE MOVILIDAD | R10: 50 | S10: 206276 | T10: 207605 | U10: =+T10-S10 -> 1329 | V10: =+U10/(R10+60+54+38+30-W10) -> 7.0384493 | W10: 43.18 | X10: =+T10 -> 207605 | Y10: 209042 | Z10: =+Y10-X10 -> 1437 | AA10: =+Z10/(W10+130+49-AB10) -> 7.100504 | AB10: 19.8 | AC10: =+Y10 -> 209042 | AD10: 210237 | AE10: =+AD10-AC10 -> 1195 | AF10: =+AE10/(AB10+30+30+110-AG10) -> 6.8995381 | AG10: 16.6 | AH10: =+AD10 -> 210237 | AI10: 211961 | AJ10: =+AI10-AH10 -> 1724 | AK10: =+AJ10/(AG10+30+50+60+30+68-AL10) -> 7.2013367 | AL10: 15.2 | AM10: =+AI10 -> 211961 | AN10: 212731 | AO10: =+AN10-AM10 -> 770 | AP10: =+AO10/(AL10+124-AQ10) -> 6.8848355 | AQ10: 27.36
A11: =+A10+1 -> 9 | B11: DAVID CRUZ ALIZARES | C11: TOYOTA 3616 BCD | E11: 381454 | F11: 0 | G11: 0 | H11: 76.3 | I11: =+E11 -> 381454 | J11: 382222 | K11: =+J11-I11 -> 768 | L11: =+K11/(56.76+70-8.65) -> 6.502413 | M11: 8.65 | N11: =+J11 -> 382222 | O11: 382454 | P11: =+O11-N11 -> 232 | Q11: =+P11/(M11+79.02-R11) -> 6.4913262 | R11: 51.93 | S11: =+O11 -> 382454 | T11: 383496 | U11: =+T11-S11 -> 1042 | V11: =+U11/(R11+73+92+69-W11) -> 6.5031517 | W11: 125.7 | X11: =+T11 -> 383496 | Y11: 384450 | Z11: =+Y11-X11 -> 954 | AA11: =+Z11/(W11+35+57+54-AB11) -> 6.5008518 | AB11: 124.95 | AC11: =+Y11 -> 384450 | AD11: 385905 | AE11: =+AD11-AC11 -> 1455 | AF11: =+AE11/(AB11+76+47.6-AG11) -> 6.50105 | AG11: 24.74 | AH11: =+AD11 -> 385905 | AI11: 386232 | AJ11: =+AI11-AH11 -> 327 | AK11: =+AJ11/(AG11+68.82+62-AL11) -> 6.5100538 | AL11: 105.33 | AM11: =+AI11 -> 386232 | AN11: 386820 | AO11: =+AN11-AM11 -> 588 | AP11: =+AO11/(AL11+75-AQ11) -> 6.4986737 | AQ11: 89.85
A12: =+A11+1 -> 10 | B12: EDGAR CORDERO CORDERO | C12: TOYOTA 2980 XSI | D12: 273682 | E12: 273956 | F12: 274 | G12: 5.4997993 | H12: 21.78 | I12: =+E12 -> 273956 | J12: 274157 | K12: =+J12-I12 -> 201 | L12: =+K12/(14.78+40-14.78) -> 5.025 | M12: 14.78 | N12: =+J12 -> 274157 | O12: 274336 | P12: =+O12-N12 -> 179 | Q12: =+P12/(M12+68.53-R12) -> 5 | R12: 47.51
A13: =+A11+1 -> 10 | B13: EDGAR CORDERO CORDERO | C13: TOYOTA 3772 UPB | D13: 446271 | E13: 446499 | F13: 228 | G13: 5.7 | H13: 61 | I13: CAMBIO DE MOVILIDAD | M13: 35 | N13: 447935 | O13: 447992 | P13: =+O13-N13 -> 57 | Q13: =+P13/(M13-R13) -> 4.9137931 | R13: 23.4 | S13: =+O13 -> 447992 | T13: 448905 | U13: =+T13-S13 -> 913 | V13: =+U13/(R13+63.97+69-W13) -> 6.4088165 | W13: 13.91
A14: =+A13+1 -> 11 | B14: EDGAR CORDERO CORDERO | C14: TOYOTA 4028 CUS | D14: 236886 | E14: 237285 | F14: 399 | G14: 4.8305085 | H14: 79.4 | I14: =+E14 -> 237285 | J14: 237469 | K14: =+J14-I14 -> 184 | L14: =+K14/(63.8+20+20-67) -> 5 | M14: 118 | N14: =+J14 -> 237469 | O14: 238892 | P14: =+O14-N14 -> 1423 | Q14: =+P14/(M14+30+31+92+60+21-R14) -> 5 | R14: 67.4 | S14: =+O14 -> 238892 | T14: 239075 | U14: =+T14-S14 -> 183 | V14: =+U14/(R14+53.17+27-W14) -> 4.9687755 | W14: 110.74 | X14: 239113 | Y14: 239850 | Z14: =+Y14-X14 -> 737 | AA14: =+Z14/(W14-35.74+113-AB14) -> 5.5 | AB14: 54 | AC14: =+Y14 -> 239850 | AD14: 240389 | AE14: =+AD14-AC14 -> 539 | AF14: =+AE14/(AB14+80-AG14) -> 5.6 | AG14: 37.75 | AH14: =+AD14 -> 240389 | AI14: 240822 | AJ14: =+AI14-AH14 -> 433 | AK14: =+AJ14/(AG14+82+83-AL14) -> 5 | AL14: 116.15 | AM14: =+AI14 -> 240822 | AN14: 241107 | AO14: =+AN14-AM14 -> 285 | AP14: =+AO14/(AL14+80+71-AQ14) -> 5 | AQ14: 210.15
A15: =+A12+1 -> 11 | B15: EDGAR MAMANI QUISPE | C15: TRACTO LOVOY 4833 TDF | D15: SIN MOVIMIENTO | E15: 18900 | F15: 18900 | G15: 1.5 | H15: 425 | I15: SIN MOVIMIENTO | J15: 18900 | K15: =+J15-I15 -> #VALUE! | L15: =+K15/(425-425) -> #VALUE! | M15: 425 | N15: =+J15 -> 18900 | O15: 20035 | P15: =+O15-N15 -> 1135 | Q15: =+P15/(M15+390-R15) -> 1.4993395 | R15: 58 | S15: =+O15 -> 20035 | T15: 20035 | U15: =+T15-S15 -> 0 | V15: =+U15/(R15-W15) -> #DIV/0! | W15: 58 | X15: =+T15 -> 20035 | Y15: 20035 | Z15: =+Y15-X15 -> 0 | AA15: =+Z15/(W15-AB15) -> #DIV/0! | AB15: 58 | AC15: =+Y15 -> 20035 | AD15: 20035 | AE15: =+AD15-AC15 -> 0 | AF15: =+AE15/(AB15-AG15) -> #DIV/0! | AG15: 58 | AH15: =+AD15 -> 20035 | AI15: 20035 | AJ15: =+AI15-AH15 -> 0 | AK15: =+AJ15/(AG15-AL15) -> #DIV/0! | AL15: 58 | AM15: =+AI15 -> 20035 | AN15: 20665 | AO15: =+AN15-AM15 -> 630 | AP15: =+AO15/(AL15+387-AQ15) -> 1.5 | AQ15: 25
A16: =+A15+1 -> 12 | B16: EDGAR MAMANI QUISPE | C16: CAMION ESTACA 4833 TFN | D16: 61877 | E16: 63310 | F16: 466 | G16: 0.9748954 | H16: 82 | I16: SIN MOVIMIENTO | K16: =+J16-I16 -> #VALUE! | L16: =+K16/(82-82) -> #VALUE! | M16: 425 | N16: 63310 | O16: 63310 | P16: =+O16-N16 -> 0 | Q16: =+P16/(M16+390-R16) -> 0 | R16: 82 | S16: =+O16 -> 63310 | T16: 63310 | U16: =+T16-S16 -> 0 | V16: =+U16/(R16-W16) -> #DIV/0! | W16: 82 | X16: =+T16 -> 63310 | Y16: SIN MOVIMIENTO | Z16: =+Y16-X16 -> #VALUE! | AA16: =+Z16/(W16-AB16) -> #VALUE! | AB16: 82 | AC16: 63310 | AD16: 63687 | AE16: =+AD16-AC16 -> 377 | AF16: =+AE16/(AB16+160-AG16) -> 5.4637681 | AG16: 173 | AH16: =+AD16 -> 63687 | AI16: 64792 | AJ16: =+AI16-AH16 -> 1105 | AK16: =+AJ16/(AG16+180-AL16) -> 3.4968354 | AL16: 37 | AM16: =+AI16 -> 64792 | AN16: 64792 | AO16: =+AN16-AM16 -> 0 | AP16: =+AO16/(AL16+180-AQ16) -> 0 | AQ16: 37
B17: EDGAR MAMANI QUISPE | C17: VOLQUETA 4506 XYY | I17: SIN MOVIMIENTO | N17: SIN MOVIMIENTO | O17: 92731 | R17: 80 | S17: =+O17 -> 92731 | T17: 93406 | U17: =+T17-S17 -> 675 | V17: =+U17/(R17+258-W17) -> 2.5 | W17: 68 | X17: =+T17 -> 93406 | Y17: 93406 | Z17: =+Y17-X17 -> 0 | AA17: =+Z17/(W17+258-AB17) -> 0 | AB17: 68 | AC17: =+Y17 -> 93406 | AD17: 93406 | AE17: =+AD17-AC17 -> 0 | AF17: =+AE17/(AB17+258-AG17) -> 0 | AG17: 68 | AH17: =+AD17 -> 93406 | AI17: 93406 | AJ17: =+AI17-AH17 -> 0 | AK17: =+AJ17/(AG17+258-AL17) -> 0 | AL17: 68 | AM17: =+AI17 -> 93406 | AN17: 93406 | AO17: =+AN17-AM17 -> 0 | AP17: =+AO17/(AL17+258-AQ17) -> 0 | AQ17: 68
A18: =+A16+1 -> 13 | B18: EDGAR PUQUI COPA | C18: TOYOTA 2859 NTA | D18: 244742 | E18: 245295 | F18: 553 | G18: 6.4997649 | H18: 0.71 | I18: =+E18 -> 245295 | J18: 245646 | K18: =+J18-I18 -> 351 | L18: =+K18/(0.71+10+30+20-6.71) -> 6.5 | M18: 6.71 | N18: =+J18 -> 245646 | O18: 245977 | P18: =+O18-N18 -> 331 | Q18: =+P18/(M18+20+43-R18) -> 6.5003928 | R18: 18.79 | S18: =+O18 -> 245977 | T18: 246200 | U18: =+T18-S18 -> 223 | V18: =+U18/(R18+38-W18) -> 6.4995628 | W18: 22.48 | X18: =+T18 -> 246200 | Y18: 246411 | Z18: =+Y18-X18 -> 211 | AA18: =+Z18/(W18+10+40-AB18) -> 6.5003081 | AB18: 40.02 | AC18: =+Y18 -> 246411 | AD18: 246581 | AE18: =+AD18-AC18 -> 170 | AF18: =+AE18/(AB18-AG18) -> 6.500956 | AG18: 13.87 | AH18: =+AD18 -> 246581 | AI18: 246809 | AJ18: =+AI18-AH18 -> 228 | AK18: =+AJ18/(AG18+38-AL18) -> 6.4994299 | AL18: 16.79 | AM18: =+AI18 -> 246809 | AN18: 246809 | AO18: =+AN18-AM18 -> 0 | AP18: =+AO18/(AL18+38-AQ18) -> 0 | AQ18: 16.79
A19: =+A18+1 -> 14 | B19: EDWIN CAMPOS BASAGOITIA | C19: TOYOTA 6000 CCS | D19: 71466 | E19: 72131 | F19: 665 | G19: 7 | H19: 104 | I19: =+E19 -> 72131 | J19: 73216 | K19: =+J19-I19 -> 1085 | L19: =+K19/(104+50+30-29) -> 7 | M19: 29 | N19: =+J19 -> 73216 | O19: 73874 | P19: =+O19-N19 -> 658 | Q19: =+P19/(M19+60.01+75-R19) -> 6.9992554 | R19: 70 | S19: =+O19 -> 73874 | T19: 74588 | U19: =+T19-S19 -> 714 | V19: =+U19/(R19+68-W19) -> 7 | W19: 36 | X19: =+T19 -> 74588 | Y19: 75211 | Z19: =+Y19-X19 -> 623 | AA19: =+Z19/(W19+59+67-AB19) -> 7 | AB19: 73 | AC19: =+Y19 -> 75211 | AD19: 76051 | AE19: =+AD19-AC19 -> 840 | AF19: =+AE19/(AB19+77+55-AG19) -> 7 | AG19: 85 | AH19: =+AD19 -> 76051 | AI19: 77136 | AJ19: =+AI19-AH19 -> 1085 | AK19: =+AJ19/(AG19+58+59-AL19) -> 7 | AL19: 47 | AM19: =+AI19 -> 77136 | AN19: 77836 | AO19: =+AN19-AM19 -> 700 | AP19: =+AO19/(AL19+67+74-AQ19) -> 7 | AQ19: 88
A20: =+A19+1 -> 15 | B20: EDWIN MOYA MENDOZA | C20: TOYOTA 2980 XIK | D20: 335659 | E20: 335959 | F20: 300 | G20: 5.604334 | H20: 110.41 | I20: =+E20 -> 335959 | J20: 336176 | K20: =+J20-I20 -> 217 | L20: =+K20/(110.41-71.69) -> 5.6043388 | M20: 71.69 | N20: =+J20 -> 336176 | O20: 336378 | P20: =+O20-N20 -> 202 | Q20: =+P20/(M20+30+30-R20) -> 5.6064391 | R20: 95.66 | S20: =+O20 -> 336378 | T20: 336728 | U20: =+T20-S20 -> 350 | V20: =+U20/(R20+44-W20) -> 5.6044836 | W20: 77.21 | X20: =+T20 -> 336728 | Y20: 336878 | Z20: =+Y20-X20 -> 150 | AB20: 80.45 | AC20: =+Y20 -> 336878 | AD20: 337106 | AE20: =+AD20-AC20 -> 228 | AF20: =+AE20/(AB20+30+30-AG20) -> 5.6074766 | AG20: 99.79 | AH20: =+AD20 -> 337106 | AI20: 337339 | AJ20: =+AI20-AH20 -> 233 | AK20: =+AJ20/(AG20+30-AL20) -> 5.1051709 | AL20: 84.15 | AM20: =+AI20 -> 337339 | AN20: 337553 | AO20: =+AN20-AM20 -> 214 | AP20: =+AO20/(AL20+30+30-AQ20) -> 5.1013111 | AQ20: 102.2
A21: =+A20+1 -> 16 | B21: EDWIN QUISPE VELIZ | C21: NISSAN 2731 YDI | D21: 422544 | E21: 422802 | F21: 258 | G21: 4.7777778 | H21: 15 | I21: SIN MOVIMIENTO | J21: 422802 | K21: =+J21-I21 -> #VALUE! | L21: =+K21/(15-15) -> #VALUE! | M21: 15 | N21: =+J21 -> 422802 | O21: 422879 | P21: =+O21-N21 -> 77 | Q21: =+P21/(M21+130-R21) -> 4.8125 | R21: 129 | S21: =+O21 -> 422879 | T21: 423046 | U21: =+T21-S21 -> 167 | V21: =+U21/(R21-W21) -> 4.7714286 | W21: 94 | X21: =+T21 -> 423046 | Y21: 423365 | Z21: =+Y21-X21 -> 319 | AA21: =+Z21/(W21-AB21) -> 4.8333333 | AB21: 28 | AC21: =+Y21 -> 423365 | AD21: 423907 | AE21: =+AD21-AC21 -> 542 | AF21: =+AE21/(AB21+117-AG21) -> 4.7964602 | AG21: 32 | AH21: =+AD21 -> 423907 | AI21: 424033 | AJ21: =+AI21-AH21 -> 126 | AK21: =+AJ21/(AG21-AL21) -> 5.04 | AL21: 7 | AM21: =+AI21 -> 424033 | AN21: 424511 | AO21: =+AN21-AM21 -> 478 | AP21: =+AO21/(AL21+123-AQ21) -> 4.877551 | AQ21: 32
A22: =+A21+1 -> 17 | B22: EDWIN QUISPE VELIZ | C22: VOLQUETA 4833 TGS | D22: SIN MOVIMIENTO | E22: 50953 | F22: 50953 | G22: 2.5 | H22: 10 | I22: SIN MOVIMIENTO | J22: 50923 | K22: =+J22-I22 -> #VALUE! | L22: =+K22/(10-10) -> #VALUE! | M22: 10 | N22: =+J22 -> 50923 | O22: 51343 | P22: =+O22-N22 -> 420 | Q22: =+P22/(M22+212-R22) -> 2.5 | R22: 54 | S22: =+O22 -> 51343 | T22: 51685 | U22: =+T22-S22 -> 342 | V22: =+U22/(R22+100-W22) -> 2.4963504 | W22: 17 | X22: =+T22 -> 51685 | Y22: SIN MOVIMIENTO | Z22: =+Y22-X22 -> #VALUE! | AA22: =+Z22/(W22+100-AB22) -> #VALUE! | AB22: 17 | AC22: 51685 | AD22: 51685 | AE22: =+AD22-AC22 -> 0 | AF22: =+AE22/(AB22+100-AG22) -> 0 | AG22: 17 | AH22: 51685 | AI22: 51685 | AJ22: =+AI22-AH22 -> 0 | AK22: =+AJ22/(AG22+100-AL22) -> 0 | AL22: 17 | AM22: 51685 | AN22: 51685 | AO22: =+AN22-AM22 -> 0 | AP22: =+AO22/(AL22+100-AQ22) -> 0 | AQ22: 17
A23: =+A22+1 -> 18 | B23: EFRAIN CUSIPUMA MARINO | C23: TOYOTA 1843 YRG | H23: 13 | I23: 0 | J23: 0 | K23: SIN MOVIMIENTO | L23: 6 | M23: 13 | N23: SIN MOVIMIENTO | Q23: 6
A24: =+A23+1 -> 19 | B24: EFRAIN CUSIPUMA MARINO | C24: CISTERNA 4687 BBS | F24: 130 | G24: 2.5 | H24: 361.9 | I24: 40604 | J24: 40604 | K24: SIN MOVIMIENTO | L24: 2.5 | M24: 361.9 | N24: SIN MOVIMIENTO | Q24: 2.5 | R24: 362
A25: =+A24+1 -> 20 | B25: EFRAIN LLAVE VARGAS | C25: TOYOTA 3027 SZI | D25: 273949 | E25: 273974 | F25: 25 | G25: 6.25 | H25: 56.1 | I25: SIN MOVIMIENTO | J25: 273974 | K25: =+J25-I25 -> #VALUE! | L25: =+K25/(17+43.1-56.1) -> #VALUE! | M25: 56.1 | N25: =+J25 -> 273974 | O25: 275624 | P25: =+O25-N25 -> 1650 | Q25: =+P25/(M25+74.5+50+80-R25) -> 6.6909976 | R25: 14 | S25: =+O25 -> 275624 | T25: 275651 | U25: =+T25-S25 -> 27 | V25: =+U25/(R25+73-50-W25) -> 6.75 | W25: 33 | X25: =+T25 -> 275651 | Y25: 276784 | Z25: =+Y25-X25 -> 1133 | AA25: =+Z25/(W25+67.5+123-AB25) -> 6.7240356 | AB25: 55 | AC25: =+Y25 -> 276784 | AD25: 276826 | AE25: =+AD25-AC25 -> 42 | AF25: =+AE25/(AB25-AG25) -> 7 | AG25: 49 | AH25: =+AD25 -> 276826 | AI25: 277267 | AJ25: =+AI25-AH25 -> 441 | AK25: =+AJ25/(AG25+56-AL25) -> 6.6818182 | AL25: 39 | AM25: =+AI25 -> 277267 | AN25: 277267 | AO25: =+AN25-AM25 -> 0 | AP25: =+AO25/(AL25+56-AQ25) -> 0 | AQ25: 39
B26: EFRAIN LLAVE VARGAS | C26: CISTERNA WOSBAGUEN 4516 NEX | S26: SIN MOVIMIENTO | X26: SIN MOVIMIENTO | AB26: 130 | AC26: 24178 | AD26: 24354 | AE26: =+AD26-AC26 -> 176 | AF26: =+AE26/(AB26+100-AG26) -> 3.3846154 | AG26: 178 | AH26: =+AD26 -> 24354 | AI26: 24463 | AJ26: =+AI26-AH26 -> 109 | AK26: =+AJ26/(AG26-AL26) -> 3.3030303 | AL26: 145 | AM26: =+AI26 -> 24463 | AN26: 24508 | AO26: =+AN26-AM26 -> 45 | AP26: =+AO26/(AL26-AQ26) -> 3.2142857 | AQ26: 131
B27: EFRAIN LLAVE VARGAS | C27: VOLQUETA 2913 FEA | S27: SIN MOVIMIENTO | X27: SIN MOVIMIENTO | AB27: 155 | AC27: 1311674 | AD27: 1312481 | AE27: =+AD27-AC27 -> 807 | AF27: =+AE27/(AB27+244-AG27) -> 2.498452 | AG27: 76 | AH27: =+AD27 -> 1312481 | AI27: 1312536 | AJ27: =+AI27-AH27 -> 55 | AK27: =+AJ27/(AG27-AL27) -> 2.5 | AL27: 54 | AM27: =+AI27 -> 1312536 | AN27: 1312536 | AO27: =+AN27-AM27 -> 0 | AP27: =+AO27/(AL27-AQ27) -> #DIV/0! | AQ27: 54
B28: EFRAIN LLAVE VARGAS | C28: CISTERNA 4833 TEI | S28: SIN MOVIMIENTO | X28: 14156 | Y28: 14156 | AB28: 48 | AC28: =+Y28 -> 14156 | AD28: 14156 | AE28: =+AD28-AC28 -> 0 | AF28: =+AE28/(AB28+100-AG28) -> 0 | AG28: 48 | AH28: =+AD28 -> 14156 | AI28: 14156 | AJ28: =+AI28-AH28 -> 0 | AK28: =+AJ28/(AG28+100-AL28) -> 0 | AL28: 48 | AM28: =+AI28 -> 14156 | AN28: 14156 | AO28: =+AN28-AM28 -> 0 | AP28: =+AO28/(AL28-AQ28) -> #DIV/0! | AQ28: 48
B29: EFRAIN LLAVE VARGAS | C29: VOLQUETA 2913 FFD | S29: SIN MOVIMIENTO | X29: 14156 | Y29: 14156 | AB29: 48 | AC29: SIN MOVIMIENTO | AH29: SIN MOVIMIENTO en mantenimiento | AM29: 69716 | AN29: 69716 | AO29: =+AN29-AM29 -> 0 | AP29: =+AO29/(AL29-AQ29) -> 0 | AQ29: 20
A30: =+A25+1 -> 21 | B30: EFRAIN QUISPE CONDORI | C30: TOYOTA 2859 NRR | F30: 466 | G30: 5.997426 | H30: 29.6 | K30: 259 | L30: =+K30/(17.3+30-7.5) -> 6.5075377 | M30: 7.5 | N30: =+J30 | O30: 366 | P30: =+O30-N30 -> #VALUE! | Q30: =+P30/(M30+30+30-R30) -> #VALUE! | R30: 11.2 | S30: =+O30 -> 366 | T30: =+S30+365 -> 731 | U30: =+T30-S30 -> 365 | V30: =+U30/(R30+30+30-W30) -> 6.4946619 | W30: 15 | X30: 0 | Y30: 232 | Z30: =+Y30-X30 -> 232 | AA30: =+Z30/(W30+30-AB30) -> 6.4985994 | AB30: 9.3 | AC30: 0 | AD30: 499 | AE30: =+AD30-AC30 -> 499 | AF30: =+AE30/(AB30+30+30+30-AG30) -> 7.0182841 | AG30: 28.2 | AH30: 0 | AI30: 437 | AJ30: =+AI30-AH30 -> 437 | AK30: =+AJ30/(AG30+30+30-AL30) -> 6.4076246 | AL30: 20 | AM30: 0 | AN30: 399 | AO30: =+AN30-AM30 -> 399 | AP30: =+AO30/(AL30+30+30-AQ30) -> 6.4563107 | AQ30: 18.2
B31: EFRAIN QUISPE CONDORI (LUIS MIGUEL RAMIREZ) | C31: TOYOTA 1142 DDK | N31: 0 | O31: 710 | P31: =+O31-N31 -> 710 | Q31: =+P31/(M31+150-R31) -> 5.5993691 | R31: 23.2 | S31: =+O31 -> 710 | U31: =+T31-S31 -> -710 | V31: =+U31/(R31+73-50-W31) -> -53.787879 | W31: 33 | X31: SIN MOVIMIENTO | AB31: 23.2 | AC31: 0 | AD31: 450 | AE31: =+AD31-AC31 -> 450 | AF31: =+AE31/(AB31+79.92-AG31) -> 4.9988891 | AG31: 13.1 | AH31: 0 | AI31: 0 | AJ31: =+AI31-AH31 -> 0 | AK31: =+AJ31/(AG31+79.92-AL31) -> 0 | AL31: 13.1 | AM31: 0 | AN31: 0 | AO31: =+AN31-AM31 -> 0 | AP31: =+AO31/(AL31+79.92-AQ31) -> 0 | AQ31: 13.1
A32: =+A30+1 -> 22 | B32: ELIAS VERA GUERRA | C32: TOYOTA XHG | D32: 446355 | E32: 446584 | F32: 229 | G32: 6.5001419 | H32: 26.75 | I32: =+E32 -> 446584 | J32: 446764 | K32: =+J32-I32 -> 180 | L32: =+K32/(26.75+40-39.06) -> 6.5005417 | M32: 39.06 | N32: =+J32 -> 446764 | O32: 448046 | P32: =+O32-N32 -> 1282 | Q32: =+P32/(M32+127.52+43.1-R32) -> 6.5000254 | R32: 12.45 | S32: =+O32 -> 448046 | T32: 448900 | U32: =+T32-S32 -> 854 | V32: =+U32/(R32+64+71.71-W32) -> 6.5002283 | W32: 16.78 | X32: =+T32 -> 448900 | Y32: 449689 | Z32: =+Y32-X32 -> 789 | AA32: =+Z32/(W32+56+50.3-AB32) -> 6.5002472 | AB32: 1.7 | AC32: =+Y32 -> 449689 | AD32: 450287 | AE32: =+AD32-AC32 -> 598 | AF32: =+AE32/(AB32+74+20-AG32) -> 6.5 | AG32: 3.7 | AH32: =+AD32 -> 450287 | AI32: 450501 | AJ32: =+AI32-AH32 -> 214 | AK32: =+AJ32/(AG32+76.51-AL32) -> 6.5006075 | AL32: 47.29 | AM32: =+AI32 -> 450501 | AN32: 450989 | AO32: =+AN32-AM32 -> 488 | AP32: =+AO32/(AL32+49.6-AQ32) -> 6.4997336 | AQ32: 21.81
A33: =+A32+1 -> 23 | B33: EMETERIO PEÑAS LIMACHI | C33: NISSAN 2721 GFP | D33: 303210 | E33: 303384 | F33: 174 | G33: 6.0020697 | H33: 17.01 | I33: SIN MOVIMIENTO en mantenimiento | J33: 303384 | M33: 17.1 | N33: =+J33 -> 303384 | O33: 303497 | P33: =+O33-N33 -> 113 | Q33: =+P33/(M33-R33) -> 6.9667078 | R33: 0.88 | S33: =+O33 -> 303497 | T33: 303840 | U33: =+T33-S33 -> 343 | V33: =+U33/(R33+55+41-W33) -> 6.0017498 | W33: 39.73 | X33: =+T33 -> 303840 | Y33: 304201 | Z33: =+Y33-X33 -> 361 | AA33: =+Z33/(W33+30+37-AB33) -> 6.0006649 | AB33: 46.57 | AC33: =+Y33 -> 304201 | AD33: 304996 | AE33: =+AD33-AC33 -> 795 | AF33: =+AE33/(AB33+47+40+41-AG33) -> 6.0009058 | AG33: 42.09 | AH33: =+AD33 -> 304996 | AI33: 304996 | AJ33: =+AI33-AH33 -> 0 | AK33: =+AJ33/(AG33+47+40+41-AL33) -> 0 | AL33: 42.09 | AM33: =+AI33 -> 304996 | AN33: 304996 | AO33: =+AN33-AM33 -> 0 | AP33: =+AO33/(AL33+47+40+41-AQ33) -> 0 | AQ33: 42.09
A34: =+A33+1 -> 24 | B34: EMETERIO PEÑAS LIMACHI | C34: TOYOTA 4829 RUY | D34: 259339 | E34: 260224 | F34: 885 | G34: 7.0004746 | H34: 38.3 | I34: SIN MOVIMIENTO en mantenimiento | N34: SIN MOVIMIENTO en mantenimiento | S34: SIN MOVIMIENTO en mantenimiento | X34: SIN MOVIMIENTO en mantenimiento | AC34: SIN MOVIMIENTO en mantenimiento | AH34: SIN MOVIMIENTO en mantenimiento | AM34: SIN MOVIMIENTO en mantenimiento
A35: =+A34+1 -> 25 | B35: ERNESTO QUISPE FLORES | C35: TOYOTA 4829 RKU | D35: 242118 | E35: 242944 | F35: 826 | G35: 7.0029674 | H35: 94.35 | I35: =+E35 -> 242944 | J35: 243158 | K35: =+J35-I35 -> 214 | L35: =+K35/(94.35-60.43) -> 6.3089623 | M35: 60.43 | N35: =+J35 -> 243158 | O35: 244620 | P35: =+O35-N35 -> 1462 | Q35: =+P35/(M35+20+55+110-R35) -> 7.0012451 | R35: 36.61 | S35: =+O35 -> 244620 | T35: 245597 | U35: =+T35-S35 -> 977 | V35: =+U35/(R35+58+49+60+21-W35) -> 6.9696105 | W35: 84.43 | X35: =+T35 -> 245597 | Y35: 247426 | Z35: =+Y35-X35 -> 1829 | AA35: =+Z35/(W35+132+110-AB35) -> 7.000689 | AB35: 65.17 | AC35: =+Y35 -> 247426 | AD35: 249658 | AE35: =+AD35-AC35 -> 2232 | AF35: =+AE35/(AB35+66+138+105+36-AG35) -> 7.0008155 | AG35: 91.35 | AH35: =+AD35 -> 249658 | AI35: 250068 | AJ35: =+AI35-AH35 -> 410 | AK35: =+AJ35/(AG35+45-AL35) -> 6.3057521 | AL35: 71.33 | AM35: =+AI35 -> 250068 | AN35: 250584 | AO35: =+AN35-AM35 -> 516 | AP35: =+AO35/(AL35+41-AQ35) -> 6.7030398 | AQ35: 35.35
B36: GABRIEL CHUCAMANI | C36: TOYOTA 2980 XTL | I36: EN MANTENIMEINTO | N36: EN MANTENIMEINTO | S36: EN MANTENIMEINTO | X36: EN MANTENIMEINTO | AB36: 20 | AC36: 491667 | AD36: 491667 | AE36: =+AD36-AC36 -> 0 | AF36: =+AE36/(AB36+102-AG36) -> 0 | AG36: 42.3 | AH36: =+AD36 -> 491667 | AI36: 493764 | AJ36: =+AI36-AH36 -> 2097 | AK36: =+AJ36/(AG36+94+52+144-AL36) -> 6.9002962 | AL36: 28.4 | AM36: =+AI36 -> 493764 | AN36: 494513 | AO36: =+AN36-AM36 -> 749 | AP36: =+AO36/(AL36+59+60+52-AQ36) -> 6.2003311 | AQ36: 78.6
A37: =+A35+1 -> 26 | B37: GERARDO CHOQUE MAMANI | C37: TOYOTA 3772 UTL | D37: 342083 | E37: 342091 | F37: 8 | G37: 5.5172414 | H37: 51.75 | I37: 342091 | J37: MANTENIMIENTO | K37: =+J37-I37 -> #VALUE! | L37: =+K37/(51.75) -> #VALUE! | M37: 51.75 | N37: =+J37 -> MANTENIMIENTO | O37: 342091 | P37: =+O37-N37 -> #VALUE! | Q37: =+P37/(M37-R37) -> #VALUE! | R37: 51.75 | S37: MANTENIMIENTO | U37: =+T37-S37 -> #VALUE! | V37: =+U37/(R37-W37) -> #VALUE! | W37: 51.75 | X37: 342091 | Y37: 342091 | Z37: =+Y37-X37 -> 0 | AA37: =+Z37/(W37-AB37) -> #DIV/0! | AB37: 51.75 | AC37: 342091 | AD37: 342091 | AE37: =+AD37-AC37 -> 0 | AF37: =+AE37/(AB37-AG37) -> #DIV/0! | AG37: 51.75 | AH37: 342091 | AI37: 342091 | AJ37: =+AI37-AH37 -> 0 | AK37: =+AJ37/(AG37-AL37) -> #DIV/0! | AL37: 51.75 | AM37: 342091 | AN37: 342091 | AO37: =+AN37-AM37 -> 0 | AP37: =+AO37/(AL37-AQ37) -> #DIV/0! | AQ37: 51.75
A38: =+A37+1 -> 27 | B38: GUZMAN LOPEZ LLANOS | C38: TOYOTA 3786 LNL | D38: 393247 | E38: 394478 | F38: 1231 | G38: 6.5001584 | H38: 52.01 | I38: =+E38 -> 394478 | J38: 394585 | K38: =+J38-I38 -> 107 | L38: =+K38/(52.01+30-65.55) -> 6.5006075 | M38: 65.55 | N38: =+J38 -> 394585 | O38: 396100 | P38: =+O38-N38 -> 1515 | Q38: =+P38/(65.55+150.17+30+70.68-87.32) -> 6.6134102 | R38: 87.32 | S38: =+O38 -> 396100 | T38: 397891 | U38: =+T38-S38 -> 1791 | V38: =+U38/(R38+45+70.87+30+72-W38) -> 6.4999637 | W38: 29.65 | X38: =+T38 -> 397891 | Y38: 398982 | Z38: =+Y38-X38 -> 1091 | AA38: =+Z38/(W38+142+84-AB38) -> 6.4998511 | AB38: 87.8 | AC38: =+Y38 -> 398982 | AD38: 400416 | AE38: =+AD38-AC38 -> 1434 | AF38: =+AE38/(AB38+100+30+30-AG38) -> 6.499864 | AG38: 27.18 | AH38: =+AD38 -> 400416 | AI38: 401845 | AJ38: =+AI38-AH38 -> 1429 | AK38: =+AJ38/(AG38+30+65+30+93.8+30.65-AL38) -> 9.1897106 | AL38: 121.13 | AM38: =+AI38 -> 401845 | AN38: 403238 | AO38: =+AN38-AM38 -> 1393 | AP38: =+AO38/(AL38+68+30+30-AQ38) -> 6.49993 | AQ38: 34.82
A39: =+A38+1 -> 28 | B39: HERNAN CHOQUE CONDORI | C39: CAMION IVECO GRUA 4710 DUK | F39: 0 | G39: 0 | H39: 89 | I39: SIN MOVIMIENTO | J39: 38390 | K39: =+J39-I39 -> #VALUE! | L39: =+K39/(297-89) -> #VALUE! | M39: 89 | N39: =+J39 -> 38390 | O39: 38400 | P39: =+O39-N39 -> 10 | Q39: =+P39/(M39+425-R39) -> 2 | R39: 509 | S39: =+O39 -> 38400 | T39: 38400 | U39: =+T39-S39 -> 0 | V39: =+U39/(R39+425-W39) -> 0 | W39: 509 | X39: =+T39 -> 38400 | Y39: SIN MOVIMIENTO | Z39: =+Y39-X39 -> #VALUE! | AA39: =+Z39/(W39+425-AB39) -> #VALUE! | AB39: 509 | AC39: 38400 | AD39: 39226 | AE39: =+AD39-AC39 -> 826 | AF39: =+AE39/(AB39-AG39) -> 1.8034934 | AG39: 51 | AH39: =+AD39 -> 39226 | AI39: 39460 | AJ39: =+AI39-AH39 -> 234 | AK39: =+AJ39/(AG39+242-AL39) -> 1.5 | AL39: 137 | AM39: =+AI39 -> 39460 | AN39: 39929 | AO39: =+AN39-AM39 -> 469 | AP39: =+AO39/(AL39+457-AQ39) -> 1.8038462 | AQ39: 334
A40: =+A39+1 -> 29 | B40: HIBERTH ALCOBA MAMANI | C40: TOYOTA 3027 SYF | D40: 431326 | E40: 432561 | F40: 1235 | G40: 5.8425584 | H40: 23.67 | I40: =+E40 -> 432561 | J40: 432661 | K40: =+J40-I40 -> 100 | L40: =+K40/(23.67-7.01) -> 6.002401 | M40: 7.01 | N40: =+J40 -> 432661 | O40: 433596 | P40: =+O40-N40 -> 935 | Q40: =+P40/(M40+30+81.7+100-R40) -> 5.9985886 | R40: 62.84 | S40: =+O40 -> 433596 | T40: 435513 | U40: =+T40-S40 -> 1917 | V40: =+U40/(R40+65.64+69.91+78+93-W40) -> 6.0020664 | W40: 50 | X40: =+T40 -> 435513 | Y40: 436459 | Z40: =+Y40-X40 -> 946 | AA40: =+Z40/(W40+76+67-AB40) -> 6.0025381 | AB40: 35.4 | AC40: =+Y40 -> 436459 | AD40: 437759 | AE40: =+AD40-AC40 -> 1300 | AF40: =+AE40/(AB40+73+85+65-AG40) -> 6.1937205 | AG40: 48.51 | AH40: =+AD40 -> 437759 | AI40: 438774 | AJ40: =+AI40-AH40 -> 1015 | AK40: =+AJ40/(AG40+61+81+76-AL40) -> 6.0294642 | AL40: 98.17 | AM40: =+AI40 -> 438774 | AN40: 438774 | AO40: =+AN40-AM40 -> 0 | AP40: =+AO40/(AL40+61+81+76-AQ40) -> 0 | AQ40: 98.17
...

Sheet Hoja1
A18: El uso de la Gasolina es para en carguio en los tanques de los vehículos y en algun caso en bidones para viajes largos que rezalizan las Unidades Ejecutoras para Proyectos y Otros en la movilidades del Gobierno Autonomo Departamental de Potosi

Sheet Hoja2
A1: 263
A2: 564.5
A3: 808
A4: 41
A5: 41
A6: 1290.5
A7: 1234.5
A8: 1123
A9: 345.5
A10: 1089
A11: 242.5
A12: 41
... A28: 5472
A29: =SUM(A1:A28) -> 27429

Sheet FORMATO BITACORA (2)
A1: REPORTE DE USO DE COMBUSTIBLE EN VEHíCULOS
A2: GESTION | C2: 2026 | K2: SECRETARIA : | M2: ADMINISTRATIVA FINANCIERA
A3: MES | C3: ENERO | K3: TIPO DE VEHICULO | M3: CAMIONETA
A4: CHOFER | C4: DANIEL MAMANI CHOQUE | K4: PLACA | M4: 2980 XPC
A5: LUGAR | C5: POTOSI | K5: COLOR | M5: PLOMO
A6: FECHA | B6: Nº VALE | C6: CANT. | D6: OBJETO DE VIAJE O TRABAJO | H6: COMBUSTIBLE | K6: KILOMETRAJE | N6: KILOMETRAJE POR LITRO GASOLINA | P6: RESPONSABLE DE VIAJE
H7: INGRESO | I7: UTILIZADO (*) | J7: SALDO | K7: SALIDA | L7: LLEGADA | M7: RECORRIDO
D8: SALDO ANTERIOR | J8: 62.43 | L8: 463577
A9: 46023 | D9: APOYO LOCAL | H9: =C9 -> 0 | I9: =+M9/N9 -> 7.1666667 | J9: =+J8+H9-I9 -> 55.263333 | K9: =+L8 -> 463577 | L9: 463620 | M9: =+L9-K9 -> 43 | N9: 6
A10: 46024 | D10: APOYO LOCAL | H10: =C10 -> 0 | I10: =+M10/N10 -> 0 | J10: =+J9+H10-I10 -> 55.263333 | K10: =+L9 -> 463620 | L10: 463620 | M10: =+L10-K10 -> 0 | N10: 6
A11: 46025 | D11: APOYO LOCAL | H11: =C11 -> 0 | I11: =+M11/N11 -> 0 | J11: =+J10+H11-I11 -> 55.263333 | K11: =+L10 -> 463620 | L11: 463620 | M11: =+L11-K11 -> 0 | N11: 6
A12: 46026 | D12: APOYO LOCAL | H12: =C12 -> 0 | I12: =+M12/N12 -> 0 | J12: =+J11+H12-I12 -> 55.263333 | K12: =+L11 -> 463620 | L12: 463620 | M12: =+L12-K12 -> 0 | N12: 6
A13: 46027 | D13: APOYO LOCAL | H13: =C13 -> 0 | I13: =+M13/N13 -> 0 | J13: =+J12+H13-I13 -> 55.263333 | K13: =+L12 -> 463620 | L13: 463620 | M13: =+L13-K13 -> 0 | N13: 6
A14: 46028 | D14: APOYO LOCAL | H14: =C14 -> 0 | I14: =+M14/N14 -> 6.3333333 | J14: =+J13+H14-I14 -> 48.93 | K14: =+L13 -> 463620 | L14: 463658 | M14: =+L14-K14 -> 38 | N14: 6
A15: 46029 | D15: APOYO LOCAL | H15: =C15 -> 0 | I15: =+M15/N15 -> 3.8333333 | J15: =+J14+H15-I15 -> 45.096667 | K15: =+L14 -> 463658 | L15: 463681 | M15: =+L15-K15 -> 23 | N15: 6
A16: 46030 | D16: APOYO LOCAL | H16: =C16 -> 0 | I16: =+M16/N16 -> 7.3333333 | J16: =+J15+H16-I16 -> 37.763333 | K16: =+L15 -> 463681 | L16: 463725 | M16: =+L16-K16 -> 44 | N16: 6
A17: 46031 | B17: 20553 | C17: 30 | D17: APOYO LOCAL | H17: =C17 -> 30 | I17: =+M17/N17 -> 7.8333333 | J17: =+J16+H17-I17 -> 59.93 | K17: =+L16 -> 463725 | L17: 463772 | M17: =+L17-K17 -> 47 | N17: 6
A18: 46032 | D18: APOYO LOCAL | H18: =C18 -> 0 | I18: =+M18/N18 -> 8 | J18: =+J17+H18-I18 -> 51.93 | K18: =+L17 -> 463772 | L18: 463820 | M18: =+L18-K18 -> 48 | N18: 6
A19: 46033 | D19: APOYO LOCAL | H19: =C19 -> 0 | I19: =+M19/N19 -> 8.1666667 | J19: =+J18+H19-I19 -> 43.763333 | K19: =+L18 -> 463820 | L19: 463869 | M19: =+L19-K19 -> 49 | N19: 6
A20: 46034 | D20: APOYO LOCAL | H20: =C20 -> 0 | I20: =+M20/N20 -> 0 | J20: =+J19+H20-I20 -> 43.763333 | K20: =+L19 -> 463869 | L20: 463869 | M20: =+L20-K20 -> 0 | N20: 6
A21: 46035 | D21: APOYO LOCAL | H21: =C21 -> 0 | I21: =+M21/N21 -> 7.8333333 | J21: =+J20+H21-I21 -> 35.93 | K21: =+L20 -> 463869 | L21: 463916 | M21: =+L21-K21 -> 47 | N21: 6
A22: 46036 | B22: 20554 | C22: 30 | D22: APOYO LOCAL | H22: =C22 -> 30 | I22: =+M22/N22 -> 7.8333333 | J22: =+J21+H22-I22 -> 58.096667 | K22: =+L21 -> 463916 | L22: 463963 | M22: =+L22-K22 -> 47 | N22: 6
A23: 46037 | D23: VIAJE MUNCIPIO DE YOCALLA SG O.S. 250 | H23: =C23 -> 0 | I23: =+M23/N23 -> 25.333333 | J23: =+J22+H23-I23 -> 32.763333 | K23: =+L22 -> 463963 | L23: 464115 | M23: =+L23-K23 -> 152 | N23: 6
A25: (*) Promedio de litro de combustible utilizado en relación a kilometros recorridos.
A26: KILOMETRAJE INICIAL | E26: =+K9 -> 463577 | G26: FIRMA CONDUCTOR | I26: CONFORMIDAD INMEDIATO SUPERIOR | K26: CONFORMIDAD MAESTRANZA | M26: CONFORMIDAD ACTIVOS FIJOS | O26: CONFORMIDAD RESP. DE COMBUSTIBLE
A27: KILOMETRAJE FINAL | E27: =+L23 -> 464115
A28: KILOMETRAJE RECORRIDO | E28: =+E27-E26 -> 538
A29: COMBUSTIBLE CARGADO EN EL PERIODO | E29: =SUM(H9:H24) -> 60
A30: COMBUSTIBLE CONSUMIDO EN EL PERIODO | E30: =SUM(I9:I23) -> 89.666667
A31: KILOMETRAJE POR LITRO GASOLINA | E31: =(SUM(N9:O23))/15 -> 6
A32: LITROS SOBRANTES PARA EL MES SIGUIENTE | E32: =+J23 -> 32.763333
A34: OBSERVACIONES:

Sheet FORMATO BITACORA
A1: GESTION | B1: 2026 | D1: REPORTE DE USO DE COMBUSTIBLE EN VEHíCULOS | L1: SECRETARIA :
A3: MES | J3: TIPO DE VEHICULO
A4: CHOFER | J4: PLACA
A5: LUGAR | J5: COLOR
A6: FECHA | B6: Nº VALE | C6: CANT. | D6: OBJETO DE VIAJE O TRABAJO | G6: COMBUSTIBLE | J6: KILOMETRAJE | M6: RESPONSABLE DE VIAJE | O6: FIRMA
G7: INGRESO | H7: UTILIZADO (*) | I7: SALDO | J7: SALIDA | K7: LLEGADA | L7: RECORRIDO
D8: SALDO ANTERIOR | I8: 14.58
I9: =+I8+G9-H9 -> #VALUE!
I10: =+I9+G10-H10 -> #VALUE!
I11: =+I10+G11-H11 -> #VALUE!
I12: =+I11+G12-H12 -> #VALUE!
I13: =+I12+G13-H13 -> #VALUE!
I14: =+I13+G14-H14 -> #VALUE!
I15: =+I14+G15-H15 -> #VALUE!
I16: =+I15+G16-H16 -> #VALUE!
I17: =+I16+G17-H17 -> #VALUE!
I18: =+I17+G18-H18 -> #VALUE!
I19: =+I18+G19-H19 -> #VALUE!
I20: =+I19+G20-H20 -> #VALUE!
I21: =+I20+G21-H21 -> #VALUE! | Q21: =H25+I25 -> 0
I22: =+I21+G22-H22 -> #VALUE!
A25: TOTALES
A26: (*) Promedio de litro de combustible utilizado en relación a kilometros recorridos.
A27: KILOMETRAJE INICIAL | F27: FIRMA CONDUCTOR | H27: CONFORMIDAD INMEDIATO SUPERIOR | J27: CONFORMIDAD MAESTRANZA | L27: CONFORMIDAD ACTIVOS FIJOS | N27: CONFORMIDAD RESP. DE COMBUSTIBLE
A28: KILOMETRAJE FINAL
A29: KILOMETRAJE RECORRIDO
A30: COMBUSTIBLE CONSUMIDO
A31: KILOMETRAJE POR LITRO GASOLINA
A32: LITROS SOBRANTES PARA EL MES SIGUIENTE
A34: OBSERVACIONES:

Sheet FORMATO BITACORA (3)
A1: REPORTE DE USO DE COMBUSTIBLE EN VEHíCULOS
A2: GESTION | C2: 2026 | K2: SECRETARIA : | M2: ADMINISTRATIVA FINANCIERA
A3: MES | C3: ENERO | K3: TIPO DE VEHICULO | M3: CAMIONETA
A4: CHOFER | C4: DANIEL MAMANI CHOQUE | K4: PLACA | M4: 2980 XPC
A5: LUGAR | C5: POTOSI | K5: COLOR | M5: PLOMO
A6: FECHA | B6: Nº VALE | C6: CANT. | D6: OBJETO DE VIAJE O TRABAJO | H6: COMBUSTIBLE | K6: KILOMETRAJE | N6: KILOMETRAJE POR LITRO GASOLINA | P6: RESPONSABLE DE VIAJE
H7: INGRESO | I7: UTILIZADO (*) | J7: SALDO | K7: SALIDA | L7: LLEGADA | M7: RECORRIDO
D8: SALDO ANTERIOR | J8: 133.9 | L8: 102100
A9: 46023 | D9: APOYO LOCAL | H9: =C9 -> 0 | I9: =+M9/N9 -> 0 | J9: =+J8+H9-I9 -> 133.9 | K9: =+L8 -> 102100 | L9: 102100 | M9: =+L9-K9 -> 0 | N9: 5
A10: 46024 | D10: APOYO LOCAL | H10: =C10 -> 0 | I10: =+M10/N10 -> 2 | J10: =+J9+H10-I10 -> 131.9 | K10: =+L9 -> 102100 | L10: 102110 | M10: =+L10-K10 -> 10 | N10: 5
A11: 46025 | D11: APOYO LOCAL | H11: =C11 -> 0 | I11: =+M11/N11 -> 2 | J11: =+J10+H11-I11 -> 129.9 | K11: =+L10 -> 102110 | L11: 102120 | M11: =+L11-K11 -> 10 | N11: 5
A12: 46026 | D12: APOYO LOCAL | H12: =C12 -> 0 | I12: =+M12/N12 -> 2 | J12: =+J11+H12-I12 -> 127.9 | K12: =+L11 -> 102120 | L12: 102130 | M12: =+L12-K12 -> 10 | N12: 5
A13: 46027 | D13: APOYO LOCAL | H13: =C13 -> 0 | I13: =+M13/N13 -> 2 | J13: =+J12+H13-I13 -> 125.9 | K13: =+L12 -> 102130 | L13: 102140 | M13: =+L13-K13 -> 10 | N13: 5
A14: 46028 | C14: 90 | D14: APOYO LOCAL | H14: =C14 -> 90 | I14: =+M14/N14 -> 2 | J14: =+J13+H14-I14 -> 213.9 | K14: =+L13 -> 102140 | L14: 102150 | M14: =+L14-K14 -> 10 | N14: 5
A15: 46029 | D15: APOYO LOCAL | H15: =C15 -> 0 | I15: =+M15/N15 -> 0 | J15: =+J14+H15-I15 -> 213.9 | K15: =+L14 -> 102150 | L15: 102150 | M15: =+L15-K15 -> 0 | N15: 5
A16: 46030 | D16: APOYO LOCAL | H16: =C16 -> 0 | I16: =+M16/N16 -> 0 | J16: =+J15+H16-I16 -> 213.9 | K16: =+L15 -> 102150 | L16: 102150 | M16: =+L16-K16 -> 0 | N16: 5
A17: 46031 | D17: APOYO LOCAL | H17: =C17 -> 0 | I17: =+M17/N17 -> 2 | J17: =+J16+H17-I17 -> 211.9 | K17: =+L16 -> 102150 | L17: 102160 | M17: =+L17-K17 -> 10 | N17: 5
A18: 46032 | D18: APOYO LOCAL | H18: =C18 -> 0 | I18: =+M18/N18 -> 2 | J18: =+J17+H18-I18 -> 209.9 | K18: =+L17 -> 102160 | L18: 102170 | M18: =+L18-K18 -> 10 | N18: 5
A19: 46033 | D19: APOYO LOCAL | H19: =C19 -> 0 | I19: =+M19/N19 -> 0 | J19: =+J18+H19-I19 -> 209.9 | K19: =+L18 -> 102170 | L19: 102170 | M19: =+L19-K19 -> 0 | N19: 5
A20: 46034 | D20: APOYO LOCAL | H20: =C20 -> 0 | I20: =+M20/N20 -> 2 | J20: =+J19+H20-I20 -> 207.9 | K20: =+L19 -> 102170 | L20: 102180 | M20: =+L20-K20 -> 10 | N20: 5
A21: 46035 | D21: APOYO LOCAL | H21: =C21 -> 0 | I21: =+M21/N21 -> 2 | J21: =+J20+H21-I21 -> 205.9 | K21: =+L20 -> 102180 | L21: 102190 | M21: =+L21-K21 -> 10 | N21: 5
A22: 46036 | D22: APOYO LOCAL | H22: =C22 -> 0 | I22: =+M22/N22 -> 0 | J22: =+J21+H22-I22 -> 205.9 | K22: =+L21 -> 102190 | L22: 102190 | M22: =+L22-K22 -> 0 | N22: 5
A23: 46037 | D23: VIAJE MUNCIPIO DE YOCALLA SG O.S. 250 | H23: =C23 -> 0 | I23: =+M23/N23 -> 0 | J23: =+J22+H23-I23 -> 205.9 | K23: =+L22 -> 102190 | L23: 102190 | M23: =+L23-K23 -> 0 | N23: 5
A25: (*) Promedio de litro de combustible utilizado en relación a kilometros recorridos.
A26: KILOMETRAJE INICIAL | E26: =+K9 -> 102100 | G26: FIRMA CONDUCTOR | I26: CONFORMIDAD INMEDIATO SUPERIOR | K26: CONFORMIDAD MAESTRANZA | M26: CONFORMIDAD ACTIVOS FIJOS | O26: CONFORMIDAD RESP. DE COMBUSTIBLE
A27: KILOMETRAJE FINAL | E27: =+L23 -> 102190
A28: KILOMETRAJE RECORRIDO | E28: =+E27-E26 -> 90
A29: COMBUSTIBLE CARGADO EN EL PERIODO | E29: =SUM(H9:H24) -> 90
A30: COMBUSTIBLE CONSUMIDO EN EL PERIODO | E30: =SUM(I9:I23) -> 18
A31: KILOMETRAJE POR LITRO GASOLINA | E31: =(SUM(N9:O23))/15 -> 5
A32: LITROS SOBRANTES PARA EL MES SIGUIENTE | E32: =+J23 -> 205.9
A34: OBSERVACIONES:

Sheet EJEMPLO JMCC (1)
A1: REPORTE DE USO DE COMBUSTIBLE EN VEHíCULOS
A2: GESTION | C2: 2025 | K2: SECRETARIA : | M2: DESPACHO
A3: MES | C3: DICIEMBRE | K3: TIPO DE VEHICULO | M3: VAGONETA - TOYOTA
A4: CHOFER | C4: JOSE MANUEL CABEZAS | K4: PLACA | M4: 3772 ULS
A5: LUGAR | C5: POTOSI | K5: COLOR | M5: BLANCO
A6: FECHA | B6: Nº VALE | C6: CANT. | D6: OBJETO DE VIAJE O TRABAJO | H6: COMBUSTIBLE | K6: KILOMETRAJE | N6: RESPONSABLE DE VIAJE | P6: FIRMA
H7: INGRESO | I7: UTILIZADO (*) | J7: SALDO | K7: SALIDA | L7: LLEGADA | M7: RECORRIDO
D8: SALDO ANTERIOR | J8: 18 | L8: 420221
A9: 45992 | D9: APOYO LOCAL | H9: =C9 -> 0 | I9: =+M9/$E$31 -> 1.6 | J9: =+J8+H9-I9 -> 16.4 | K9: =+L8 -> 420221 | L9: =+L8+8 -> 420229 | M9: =+L9-K9 -> 8
A10: 45993 | B10: 14727 | C10: 75 | D10: APOYO LOCAL | H10: =C10 -> 75 | I10: =+M10/$E$31 -> 1.2 | J10: =+J9+H10-I10 -> 90.2 | K10: =+L9 -> 420229 | L10: =+L9+6 -> 420235 | M10: =+L10-K10 -> 6
A11: 45994 | D11: APOYO LOCAL | H11: =C11 -> 0 | I11: =+M11/$E$31 -> 8.4 | J11: =+J10+H11-I11 -> 81.8 | K11: =+L10 -> 420235 | L11: =+L10+42 -> 420277 | M11: =+L11-K11 -> 42
A12: 45995 | D12: APOYO LOCAL | H12: =C12 -> 0 | I12: =+M12/$E$31 -> 7.2 | J12: =+J11+H12-I12 -> 74.6 | K12: =+L11 -> 420277 | L12: =+L11+36 -> 420313 | M12: =+L12-K12 -> 36
A13: 45996 | D13: APOYO LOCAL | H13: =C13 -> 0 | I13: =+M13/$E$31 -> 5 | J13: =+J12+H13-I13 -> 69.6 | K13: =+L12 -> 420313 | L13: =+L12+25 -> 420338 | M13: =+L13-K13 -> 25
A14: 45997 | D14: APOYO LOCAL | H14: =C14 -> 0 | I14: =+M14/$E$31 -> 0 | J14: =+J13+H14-I14 -> 69.6 | K14: =+L13 -> 420338 | L14: =+L13+0 -> 420338 | M14: =+L14-K14 -> 0
A15: 45998 | D15: APOYO LOCAL | H15: =C15 -> 0 | I15: =+M15/$E$31 -> 0 | J15: =+J14+H15-I15 -> 69.6 | K15: =+L14 -> 420338 | L15: =+L14+0 -> 420338 | M15: =+L15-K15 -> 0
A16: 45999 | D16: APOYO LOCAL | H16: =C16 -> 0 | I16: =+M16/$E$31 -> 1.8 | J16: =+J15+H16-I16 -> 67.8 | K16: =+L15 -> 420338 | L16: =+L15+9 -> 420347 | M16: =+L16-K16 -> 9
A17: 46000 | D17: APOYO LOCAL | H17: =C17 -> 0 | I17: =+M17/$E$31 -> 0 | J17: =+J16+H17-I17 -> 67.8 | K17: =+L16 -> 420347 | L17: =+L16+0 -> 420347 | M17: =+L17-K17 -> 0
A18: 46001 | D18: APOYO LOCAL | H18: =C18 -> 0 | I18: =+M18/$E$31 -> 9.6 | J18: =+J17+H18-I18 -> 58.2 | K18: =+L17 -> 420347 | L18: =+L17+48 -> 420395 | M18: =+L18-K18 -> 48
A19: 46002 | B19: COMPRA | C19: 40 | D19: APOYO LOCAL | H19: =C19 -> 40 | I19: =+M19/$E$31 -> 22 | J19: =+J18+H19-I19 -> 76.2 | K19: =+L18 -> 420395 | L19: =+L18+110 -> 420505 | M19: =+L19-K19 -> 110
A20: 46003 | D20: APOYO LOCAL | H20: =C20 -> 0 | I20: =+M20/$E$31 -> 5.8 | J20: =+J19+H20-I20 -> 70.4 | K20: =+L19 -> 420505 | L20: =+L19+29 -> 420534 | M20: =+L20-K20 -> 29
A21: 46004 | D21: APOYO LOCAL | H21: =C21 -> 0 | I21: =+M21/$E$31 -> 0 | J21: =+J20+H21-I21 -> 70.4 | K21: =+L20 -> 420534 | L21: =+L20+0 -> 420534 | M21: =+L21-K21 -> 0
A22: 46005 | D22: APOYO LOCAL | H22: =C22 -> 0 | I22: =+M22/$E$31 -> 0 | J22: =+J21+H22-I22 -> 70.4 | K22: =+L21 -> 420534 | L22: =+L21+0 -> 420534 | M22: =+L22-K22 -> 0
A23: 46006 | D23: APOYO LOCAL | H23: =C23 -> 0 | I23: =+M23/$E$31 -> 6.4 | J23: =+J22+H23-I23 -> 64 | K23: =+L22 -> 420534 | L23: =+L22+32 -> 420566 | M23: =+L23-K23 -> 32
A25: (*) Promedio de litro de combustible utilizado en relación a kilometros recorridos.
A26: KILOMETRAJE INICIAL | E26: =+K9 -> 420221 | G26: FIRMA CONDUCTOR | I26: CONFORMIDAD INMEDIATO SUPERIOR | K26: CONFORMIDAD MAESTRANZA | M26: CONFORMIDAD ACTIVOS FIJOS | O26: CONFORMIDAD RESP. DE COMBUSTIBLE
A27: KILOMETRAJE FINAL | E27: =+L23 -> 420566
A28: KILOMETRAJE RECORRIDO | E28: =+E27-E26 -> 345
A29: COMBUSTIBLE CARGADO EN EL PERIODO | E29: =SUM(H9:H24) -> 115
A30: COMBUSTIBLE CONSUMIDO EN EL PERIODO | E30: =SUM(I9:I23) -> 69
A31: KILOMETRAJE POR LITRO GASOLINA | E31: 5
A32: LITROS SOBRANTES PARA EL MES SIGUIENTE | E32: =+J23 -> 64
A34: OBSERVACIONES: | C34: En fecha 11 de diciembre se cargo combustible 40 Litros de forma particular, para su reposición si corresponde

Sheet EJEMPLO JMCC (2)
A1: REPORTE DE USO DE COMBUSTIBLE EN VEHíCULOS
A2: GESTION | C2: 2025 | K2: SECRETARIA : | M2: DESPACHO
A3: MES | C3: DICIEMBRE | K3: TIPO DE VEHICULO | M3: VAGONETA - TOYOTA
A4: CHOFER | C4: JOSE MANUEL CABEZAS | K4: PLACA | M4: 3772 ULS
A5: LUGAR | C5: POTOSI | K5: COLOR | M5: BLANCO
A6: FECHA | B6: Nº VALE | C6: CANT. | D6: OBJETO DE VIAJE O TRABAJO | H6: COMBUSTIBLE | K6: KILOMETRAJE | N6: RESPONSABLE DE VIAJE | P6: FIRMA
H7: INGRESO | I7: UTILIZADO (*) | J7: SALDO | K7: SALIDA | L7: LLEGADA | M7: RECORRIDO
D8: SALDO ANTERIOR | J8: =+'EJEMPLO JMCC (1)'!E32 -> 64 | L8: =+'EJEMPLO JMCC (1)'!E27 -> 420566
A9: 46007 | D9: APOYO LOCAL | H9: =C9 -> 0 | I9: =+M9/$E$31 -> 3.6 | J9: =+J8+H9-I9 -> 60.4 | K9: =+L8 -> 420566 | L9: =+L8+18 -> 420584 | M9: =+L9-K9 -> 18
A10: 46008 | D10: APOYO LOCAL | H10: =C10 -> 0 | I10: =+M10/$E$31 -> 7.2 | J10: =+J9+H10-I10 -> 53.2 | K10: =+L9 -> 420584 | L10: =+L9+36 -> 420620 | M10: =+L10-K10 -> 36
A11: 46009 | D11: APOYO LOCAL | H11: =C11 -> 0 | I11: =+M11/$E$31 -> 8.4 | J11: =+J10+H11-I11 -> 44.8 | K11: =+L10 -> 420620 | L11: =+L10+42 -> 420662 | M11: =+L11-K11 -> 42
A12: 46010 | B12: DEP | C12: 20 | D12: APOYO LOCAL | H12: =C12 -> 20 | I12: =+M12/$E$31 -> 27.2 | J12: =+J11+H12-I12 -> 37.6 | K12: =+L11 -> 420662 | L12: =+L11+136 -> 420798 | M12: =+L12-K12 -> 136
A13: 46011 | D13: APOYO LOCAL | H13: =C13 -> 0 | I13: =+M13/$E$31 -> 0 | J13: =+J12+H13-I13 -> 37.6 | K13: =+L12 -> 420798 | L13: =+L12+0 -> 420798 | M13: =+L13-K13 -> 0
A14: 46012 | D14: APOYO LOCAL | H14: =C14 -> 0 | I14: =+M14/$E$31 -> 0 | J14: =+J13+H14-I14 -> 37.6 | K14: =+L13 -> 420798 | L14: =+L13+0 -> 420798 | M14: =+L14-K14 -> 0
A15: 46013 | D15: APOYO LOCAL | H15: =C15 -> 0 | I15: =+M15/$E$31 -> 0 | J15: =+J14+H15-I15 -> 37.6 | K15: =+L14 -> 420798 | L15: =+L14+0 -> 420798 | M15: =+L15-K15 -> 0
A16: 46014 | B16: 14728 | C16: 115 | D16: APOYO LOCAL | H16: =C16 -> 115 | I16: =+M16/$E$31 -> 23.8 | J16: =+J15+H16-I16 -> 128.8 | K16: =+L15 -> 420798 | L16: =+L15+119 -> 420917 | M16: =+L16-K16 -> 119
A17: 46015 | D17: APOYO LOCAL | H17: =C17 -> 0 | I17: =+M17/$E$31 -> 5 | J17: =+J16+H17-I17 -> 123.8 | K17: =+L16 -> 420917 | L17: =+L16+25 -> 420942 | M17: =+L17-K17 -> 25
A18: 46016 | D18: APOYO LOCAL | H18: =C18 -> 0 | I18: =+M18/$E$31 -> 0 | J18: =+J17+H18-I18 -> 123.8 | K18: =+L17 -> 420942 | L18: =+L17+0 -> 420942 | M18: =+L18-K18 -> 0
A19: 46017 | D19: APOYO LOCAL | H19: =C19 -> 0 | I19: =+M19/$E$31 -> 37.4 | J19: =+J18+H19-I19 -> 86.4 | K19: =+L18 -> 420942 | L19: =+L18+187 -> 421129 | M19: =+L19-K19 -> 187
A20: 46018 | D20: APOYO LOCAL | H20: =C20 -> 0 | I20: =+M20/$E$31 -> 0 | J20: =+J19+H20-I20 -> 86.4 | K20: =+L19 -> 421129 | L20: =+L19+0 -> 421129 | M20: =+L20-K20 -> 0
A21: 46019 | D21: APOYO LOCAL | H21: =C21 -> 0 | I21: =+M21/$E$31 -> 0 | J21: =+J20+H21-I21 -> 86.4 | K21: =+L20 -> 421129 | L21: =+L20+0 -> 421129 | M21: =+L21-K21 -> 0
A22: 46020 | D22: APOYO LOCAL | H22: =C22 -> 0 | I22: =+M22/$E$31 -> 18.6 | J22: =+J21+H22-I22 -> 67.8 | K22: =+L21 -> 421129 | L22: =+L21+93 -> 421222 | M22: =+L22-K22 -> 93
A23: 46021 | D23: APOYO LOCAL | H23: =C23 -> 0 | I23: =+M23/$E$31 -> 6.4 | J23: =+J22+H23-I23 -> 61.4 | K23: =+L22 -> 421222 | L23: =+L22+32 -> 421254 | M23: =+L23-K23 -> 32
A24: 46022 | D24: APOYO LOCAL | H24: =C24 -> 0 | I24: =+M24/$E$31 -> 5 | J24: =+J23+H24-I24 -> 56.4 | K24: =+L23 -> 421254 | L24: =+L23+25 -> 421279 | M24: =+L24-K24 -> 25
A25: (*) Promedio de litro de combustible utilizado en relación a kilometros recorridos.
A26: KILOMETRAJE INICIAL | E26: =+K9 -> 420566 | G26: FIRMA CONDUCTOR | I26: CONFORMIDAD INMEDIATO SUPERIOR | K26: CONFORMIDAD MAESTRANZA | M26: CONFORMIDAD ACTIVOS FIJOS | O26: CONFORMIDAD RESP. DE COMBUSTIBLE
A27: KILOMETRAJE FINAL | E27: =+L24 -> 421279
A28: KILOMETRAJE RECORRIDO | E28: =+E27-E26 -> 713
A29: COMBUSTIBLE CARGADO EN EL PERIODO | E29: =SUM(H9:H24) -> 135
A30: COMBUSTIBLE CONSUMIDO EN EL PERIODO | E30: =SUM(I9:I24) -> 142.6
A31: KILOMETRAJE POR LITRO GASOLINA | E31: 5
A32: LITROS SOBRANTES PARA EL MES SIGUIENTE | E32: =+J24 -> 56.4
A34: OBSERVACIONES:

Sheet EJEMPLO JMCC (3)
A1: REPORTE DE USO DE COMBUSTIBLE EN VEHíCULOS
A2: GESTION | C2: 2026 | K2: SECRETARIA : | M2: DESPACHO
A3: MES | C3: ENERO | K3: TIPO DE VEHICULO | M3: VAGONETA - TOYOTA
A4: CHOFER | C4: JOSE MANUEL CABEZAS | K4: PLACA | M4: 3772 ULS
A5: LUGAR | C5: POTOSI | K5: COLOR | M5: BLANCO
A6: FECHA | B6: Nº VALE | C6: CANT. | D6: OBJETO DE VIAJE O TRABAJO | H6: COMBUSTIBLE | K6: KILOMETRAJE | N6: RESPONSABLE DE VIAJE | P6: FIRMA
H7: INGRESO | I7: UTILIZADO (*) | J7: SALDO | K7: SALIDA | L7: LLEGADA | M7: RECORRIDO
D8: SALDO ANTERIOR | J8: =+'EJEMPLO JMCC (2)'!E32 -> 56.4 | L8: =+'EJEMPLO JMCC (2)'!E27 -> 421279
A9: 46023 | D9: APOYO LOCAL | H9: =C9 -> 0 | I9: =+M9/$E$31 -> 0 | J9: =+J8+H9-I9 -> 56.4 | K9: =+L8 -> 421279 | L9: =+L8+0 -> 421279 | M9: =+L9-K9 -> 0
A10: 46024 | D10: APOYO LOCAL | H10: =C10 -> 0 | I10: =+M10/$E$31 -> 1 | J10: =+J9+H10-I10 -> 55.4 | K10: =+L9 -> 421279 | L10: =+L9+5 -> 421284 | M10: =+L10-K10 -> 5
A11: 46025 | D11: APOYO LOCAL | H11: =C11 -> 0 | I11: =+M11/$E$31 -> 0 | J11: =+J10+H11-I11 -> 55.4 | K11: =+L10 -> 421284 | L11: =+L10+0 -> 421284 | M11: =+L11-K11 -> 0
A12: 46026 | D12: APOYO LOCAL | H12: =C12 -> 0 | I12: =+M12/$E$31 -> 0 | J12: =+J11+H12-I12 -> 55.4 | K12: =+L11 -> 421284 | L12: =+L11+0 -> 421284 | M12: =+L12-K12 -> 0
A13: 46027 | D13: APOYO LOCAL | H13: =C13 -> 0 | I13: =+M13/$E$31 -> 0.6 | J13: =+J12+H13-I13 -> 54.8 | K13: =+L12 -> 421284 | L13: =+L12+3 -> 421287 | M13: =+L13-K13 -> 3
A14: 46028 | D14: APOYO LOCAL | H14: =C14 -> 0 | I14: =+M14/$E$31 -> 0.6 | J14: =+J13+H14-I14 -> 54.2 | K14: =+L13 -> 421287 | L14: =+L13+3 -> 421290 | M14: =+L14-K14 -> 3
A15: 46029 | D15: APOYO LOCAL | H15: =C15 -> 0 | I15: =+M15/$E$31 -> 1 | J15: =+J14+H15-I15 -> 53.2 | K15: =+L14 -> 421290 | L15: =+L14+5 -> 421295 | M15: =+L15-K15 -> 5
A16: 46030 | D16: APOYO LOCAL | H16: =C16 -> 0 | I16: =+M16/$E$31 -> 0.6 | J16: =+J15+H16-I16 -> 52.6 | K16: =+L15 -> 421295 | L16: =+L15+3 -> 421298 | M16: =+L16-K16 -> 3
A17: 46031 | D17: APOYO LOCAL | H17: =C17 -> 0 | I17: =+M17/$E$31 -> 0 | J17: =+J16+H17-I17 -> 52.6 | K17: =+L16 -> 421298 | L17: =+L16+0 -> 421298 | M17: =+L17-K17 -> 0
A18: 46032 | D18: APOYO LOCAL | H18: =C18 -> 0 | I18: =+M18/$E$31 -> 0 | J18: =+J17+H18-I18 -> 52.6 | K18: =+L17 -> 421298 | L18: =+L17+0 -> 421298 | M18: =+L18-K18 -> 0
A19: 46033 | D19: APOYO LOCAL | H19: =C19 -> 0 | I19: =+M19/$E$31 -> 0 | J19: =+J18+H19-I19 -> 52.6 | K19: =+L18 -> 421298 | L19: =+L18+0 -> 421298 | M19: =+L19-K19 -> 0
A20: 46034 | D20: APOYO LOCAL | H20: =C20 -> 0 | I20: =+M20/$E$31 -> 1.2 | J20: =+J19+H20-I20 -> 51.4 | K20: =+L19 -> 421298 | L20: =+L19+6 -> 421304 | M20: =+L20-K20 -> 6
A21: 46035 | B21: 14729 | C21: 40 | D21: APOYO LOCAL | H21: =C21 -> 40 | I21: =+M21/$E$31 -> 2 | J21: =+J20+H21-I21 -> 89.4 | K21: =+L20 -> 421304 | L21: =+L20+10 -> 421314 | M21: =+L21-K21 -> 10
A22: 46036 | D22: APOYO LOCAL | H22: =C22 -> 0 | I22: =+M22/$E$31 -> 1 | J22: =+J21+H22-I22 -> 88.4 | K22: =+L21 -> 421314 | L22: =+L21+5 -> 421319 | M22: =+L22-K22 -> 5
A23: 46037 | D23: APOYO LOCAL | H23: =C23 -> 0 | I23: =+M23/$E$31 -> 4.4 | J23: =+J22+H23-I23 -> 84 | K23: =+L22 -> 421319 | L23: =+L22+22 -> 421341 | M23: =+L23-K23 -> 22
A25: (*) Promedio de litro de combustible utilizado en relación a kilometros recorridos.
A26: KILOMETRAJE INICIAL | E26: =+K9 -> 421279 | G26: FIRMA CONDUCTOR | I26: CONFORMIDAD INMEDIATO SUPERIOR | K26: CONFORMIDAD MAESTRANZA | M26: CONFORMIDAD ACTIVOS FIJOS | O26: CONFORMIDAD RESP. DE COMBUSTIBLE
A27: KILOMETRAJE FINAL | E27: =+L23 -> 421341
A28: KILOMETRAJE RECORRIDO | E28: =+E27-E26 -> 62
A29: COMBUSTIBLE CARGADO EN EL PERIODO | E29: =SUM(H9:H24) -> 40
A30: COMBUSTIBLE CONSUMIDO EN EL PERIODO | E30: =SUM(I9:I23) -> 12.4
A31: KILOMETRAJE POR LITRO GASOLINA | E31: 5
A32: LITROS SOBRANTES PARA EL MES SIGUIENTE | E32: =+J23 -> 84
A34: OBSERVACIONES:

Sheet EJEMPLO JMCC (4)
A1: REPORTE DE USO DE COMBUSTIBLE EN VEHíCULOS
A2: GESTION | C2: 2026 | K2: SECRETARIA : | M2: DESPACHO
A3: MES | C3: ENERO | K3: TIPO DE VEHICULO | M3: VAGONETA - TOYOTA
A4: CHOFER | C4: JOSE MANUEL CABEZAS | K4: PLACA | M4: 3772 ULS
A5: LUGAR | C5: POTOSI | K5: COLOR | M5: BLANCO
A6: FECHA | B6: Nº VALE | C6: CANT. | D6: OBJETO DE VIAJE O TRABAJO | H6: COMBUSTIBLE | K6: KILOMETRAJE | N6: RESPONSABLE DE VIAJE | P6: FIRMA
H7: INGRESO | I7: UTILIZADO (*) | J7: SALDO | K7: SALIDA | L7: LLEGADA | M7: RECORRIDO
D8: SALDO ANTERIOR | J8: =+'EJEMPLO JMCC (3)'!E32 -> 84 | L8: =+'EJEMPLO JMCC (3)'!E27 -> 421341
A9: 46038 | B9: 14730 | C9: 60 | D9: APOYO LOCAL | H9: =C9 -> 60 | I9: =+M9/$E$31 -> 38 | J9: =+J8+H9-I9 -> 106 | K9: =+L8 -> 421341 | L9: =+L8+190 -> 421531 | M9: =+L9-K9 -> 190
A10: =+A9+1 -> 46039 | D10: APOYO LOCAL | H10: =C10 -> 0 | I10: =+M10/$E$31 -> 0 | J10: =+J9+H10-I10 -> 106 | K10: =+L9 -> 421531 | L10: =+L9+0 -> 421531 | M10: =+L10-K10 -> 0
A11: =+A10+1 -> 46040 | D11: APOYO LOCAL | H11: =C11 -> 0 | I11: =+M11/$E$31 -> 0 | J11: =+J10+H11-I11 -> 106 | K11: =+L10 -> 421531 | L11: =+L10+0 -> 421531 | M11: =+L11-K11 -> 0
A12: =+A11+1 -> 46041 | D12: APOYO LOCAL | H12: =C12 -> 0 | I12: =+M12/$E$31 -> 11 | J12: =+J11+H12-I12 -> 95 | K12: =+L11 -> 421531 | L12: =+L11+55 -> 421586 | M12: =+L12-K12 -> 55
A13: =+A12+1 -> 46042 | B13: 14734 | C13: 60 | D13: APOYO LOCAL | H13: =C13 -> 60 | I13: =+M13/$E$31 -> 50 | J13: =+J12+H13-I13 -> 105 | K13: =+L12 -> 421586 | L13: =+L12+250 -> 421836 | M13: =+L13-K13 -> 250
A14: =+A13+1 -> 46043 | B14: 14731 | C14: 96 | D14: APOYO LOCAL | H14: =C14 -> 96 | I14: =+M14/$E$31 -> 28 | J14: =+J13+H14-I14 -> 173 | K14: =+L13 -> 421836 | L14: =+L13+140 -> 421976 | M14: =+L14-K14 -> 140
A15: =+A14+1 -> 46044 | D15: APOYO LOCAL | H15: =C15 -> 0 | I15: =+M15/$E$31 -> 7.4 | J15: =+J14+H15-I15 -> 165.6 | K15: =+L14 -> 421976 | L15: =+L14+37 -> 422013 | M15: =+L15-K15 -> 37
A16: =+A15+1 -> 46045 | D16: APOYO LOCAL | H16: =C16 -> 0 | I16: =+M16/$E$31 -> 23.8 | J16: =+J15+H16-I16 -> 141.8 | K16: =+L15 -> 422013 | L16: =+L15+119 -> 422132 | M16: =+L16-K16 -> 119
A17: =+A16+1 -> 46046 | D17: APOYO LOCAL | H17: =C17 -> 0 | I17: =+M17/$E$31 -> 0 | J17: =+J16+H17-I17 -> 141.8 | K17: =+L16 -> 422132 | L17: =+L16+0 -> 422132 | M17: =+L17-K17 -> 0
A18: =+A17+1 -> 46047 | D18: APOYO LOCAL | H18: =C18 -> 0 | I18: =+M18/$E$31 -> 0 | J18: =+J17+H18-I18 -> 141.8 | K18: =+L17 -> 422132 | L18: =+L17+0 -> 422132 | M18: =+L18-K18 -> 0
A19: =+A18+1 -> 46048 | D19: APOYO LOCAL | H19: =C19 -> 0 | I19: =+M19/$E$31 -> 68.2 | J19: =+J18+H19-I19 -> 73.6 | K19: =+L18 -> 422132 | L19: =+L18+341 -> 422473 | M19: =+L19-K19 -> 341
A20: =+A19+1 -> 46049 | D20: APOYO LOCAL | H20: =C20 -> 0 | I20: =+M20/$E$31 -> 0 | J20: =+J19+H20-I20 -> 73.6 | K20: =+L19 -> 422473 | L20: =+L19+0 -> 422473 | M20: =+L20-K20 -> 0
A21: =+A20+1 -> 46050 | B21: 14733 | C21: 150.2 | D21: APOYO LOCAL | H21: =C21 -> 150.2 | I21: =+M21/$E$31 -> 0 | J21: =+J20+H21-I21 -> 223.8 | K21: =+L20 -> 422473 | L21: =+L20+0 -> 422473 | M21: =+L21-K21 -> 0
A22: =+A21+1 -> 46051 | D22: APOYO LOCAL | H22: =C22 -> 0 | I22: =+M22/$E$31 -> 68.8 | J22: =+J21+H22-I22 -> 155 | K22: =+L21 -> 422473 | L22: =+L21+344 -> 422817 | M22: =+L22-K22 -> 344
A23: =+A22+1 -> 46052 | D23: APOYO LOCAL | H23: =C23 -> 0 | I23: =+M23/$E$31 -> 52.6 | J23: =+J22+H23-I23 -> 102.4 | K23: =+L22 -> 422817 | L23: =+L22+263 -> 423080 | M23: =+L23-K23 -> 263
A24: =+A23+1 -> 46053 | D24: APOYO LOCAL | H24: =C24 -> 0 | I24: =+M24/$E$31 -> 24 | J24: =+J23+H24-I24 -> 78.4 | K24: =+L23 -> 423080 | L24: =+L23+120 -> 423200 | M24: =+L24-K24 -> 120
A25: (*) Promedio de litro de combustible utilizado en relación a kilometros recorridos.
A26: KILOMETRAJE INICIAL | E26: =+K9 -> 421341 | G26: FIRMA CONDUCTOR | I26: CONFORMIDAD INMEDIATO SUPERIOR | K26: CONFORMIDAD MAESTRANZA | M26: CONFORMIDAD ACTIVOS FIJOS | O26: CONFORMIDAD RESP. DE COMBUSTIBLE
A27: KILOMETRAJE FINAL | E27: =+L24 -> 423200
A28: KILOMETRAJE RECORRIDO | E28: =+E27-E26 -> 1859
A29: COMBUSTIBLE CARGADO EN EL PERIODO | E29: =SUM(H9:H24) -> 366.2
A30: COMBUSTIBLE CONSUMIDO EN EL PERIODO | E30: =SUM(I9:I24) -> 371.8
A31: KILOMETRAJE POR LITRO GASOLINA | E31: 5
A32: LITROS SOBRANTES PARA EL MES SIGUIENTE | E32: =+J24 -> 78.4
A34: OBSERVACIONES:

Sheet EJEMPLO JMCC (5)
A1: REPORTE DE USO DE COMBUSTIBLE EN VEHíCULOS
A2: GESTION | C2: 2026 | K2: SECRETARIA : | M2: DESPACHO
A3: MES | C3: FEBRERO | K3: TIPO DE VEHICULO | M3: VAGONETA - TOYOTA
A4: CHOFER | C4: JOSE MANUEL CABEZAS | K4: PLACA | M4: 3772 ULS
A5: LUGAR | C5: POTOSI | K5: COLOR | M5: BLANCO
A6: FECHA | B6: Nº VALE | C6: CANT. | D6: OBJETO DE VIAJE O TRABAJO | H6: COMBUSTIBLE | K6: KILOMETRAJE | N6: RESPONSABLE DE VIAJE | P6: FIRMA
H7: INGRESO | I7: UTILIZADO (*) | J7: SALDO | K7: SALIDA | L7: LLEGADA | M7: RECORRIDO
D8: SALDO ANTERIOR | J8: =+'EJEMPLO JMCC (4)'!E32 -> 78.4 | L8: =+'EJEMPLO JMCC (4)'!E27 -> 423200
A9: 46054 | D9: APOYO LOCAL | H9: =C9 -> 0 | I9: =+M9/$E$31 -> 0 | J9: =+J8+H9-I9 -> 78.4 | K9: =+L8 -> 423200 | L9: =+L8+0 -> 423200 | M9: =+L9-K9 -> 0
A10: =+A9+1 -> 46055 | B10: 14732 | C10: 79.76 | D10: APOYO LOCAL | H10: =C10 -> 79.76 | I10: =+M10/$E$31 -> 11 | J10: =+J9+H10-I10 -> 147.16 | K10: =+L9 -> 423200 | L10: =+L9+55 -> 423255 | M10: =+L10-K10 -> 55
A11: =+A10+1 -> 46056 | D11: APOYO LOCAL | H11: =C11 -> 0 | I11: =+M11/$E$31 -> 2.4 | J11: =+J10+H11-I11 -> 144.76 | K11: =+L10 -> 423255 | L11: =+L10+12 -> 423267 | M11: =+L11-K11 -> 12
A12: =+A11+1 -> 46057 | D12: APOYO LOCAL | H12: =C12 -> 0 | I12: =+M12/$E$31 -> 5 | J12: =+J11+H12-I12 -> 139.76 | K12: =+L11 -> 423267 | L12: =+L11+25 -> 423292 | M12: =+L12-K12 -> 25
A13: =+A12+1 -> 46058 | D13: APOYO LOCAL | H13: =C13 -> 0 | I13: =+M13/$E$31 -> 5 | J13: =+J12+H13-I13 -> 134.76 | K13: =+L12 -> 423292 | L13: =+L12+25 -> 423317 | M13: =+L13-K13 -> 25
A14: =+A13+1 -> 46059 | D14: APOYO LOCAL | H14: =C14 -> 0 | I14: =+M14/$E$31 -> 19 | J14: =+J13+H14-I14 -> 115.76 | K14: =+L13 -> 423317 | L14: =+L13+95 -> 423412 | M14: =+L14-K14 -> 95
A15: =+A14+1 -> 46060 | D15: APOYO LOCAL | H15: =C15 -> 0 | I15: =+M15/$E$31 -> 0 | J15: =+J14+H15-I15 -> 115.76 | K15: =+L14 -> 423412 | L15: =+L14+0 -> 423412 | M15: =+L15-K15 -> 0
A16: =+A15+1 -> 46061 | D16: APOYO LOCAL | H16: =C16 -> 0 | I16: =+M16/$E$31 -> 0 | J16: =+J15+H16-I16 -> 115.76 | K16: =+L15 -> 423412 | L16: =+L15+0 -> 423412 | M16: =+L16-K16 -> 0
A17: =+A16+1 -> 46062 | D17: APOYO LOCAL | H17: =C17 -> 0 | I17: =+M17/$E$31 -> 3 | J17: =+J16+H17-I17 -> 112.76 | K17: =+L16 -> 423412 | L17: =+L16+15 -> 423427 | M17: =+L17-K17 -> 15
A18: =+A17+1 -> 46063 | D18: APOYO LOCAL | H18: =C18 -> 0 | I18: =+M18/$E$31 -> 22.8 | J18: =+J17+H18-I18 -> 89.96 | K18: =+L17 -> 423427 | L18: =+L17+114 -> 423541 | M18: =+L18-K18 -> 114
A19: =+A18+1 -> 46064 | D19: APOYO LOCAL | H19: =C19 -> 0 | I19: =+M19/$E$31 -> 0.4 | J19: =+J18+H19-I19 -> 89.56 | K19: =+L18 -> 423541 | L19: =+L18+2 -> 423543 | M19: =+L19-K19 -> 2
A20: =+A19+1 -> 46065 | D20: APOYO LOCAL | H20: =C20 -> 0 | I20: =+M20/$E$31 -> 0.8 | J20: =+J19+H20-I20 -> 88.76 | K20: =+L19 -> 423543 | L20: =+L19+4 -> 423547 | M20: =+L20-K20 -> 4
A21: =+A20+1 -> 46066 | D21: APOYO LOCAL | H21: =C21 -> 0 | I21: =+M21/$E$31 -> 23 | J21: =+J20+H21-I21 -> 65.76 | K21: =+L20 -> 423547 | L21: =+L20+115 -> 423662 | M21: =+L21-K21 -> 115
A22: =+A21+1 -> 46067 | D22: APOYO LOCAL | H22: =C22 -> 0 | I22: =+M22/$E$31 -> 0 | J22: =+J21+H22-I22 -> 65.76 | K22: =+L21 -> 423662 | L22: =+L21+0 -> 423662 | M22: =+L22-K22 -> 0
A23: =+A22+1 -> 46068 | D23: APOYO LOCAL | H23: =C23 -> 0 | I23: =+M23/$E$31 -> 0 | J23: =+J22+H23-I23 -> 65.76 | K23: =+L22 -> 423662 | L23: =+L22+0 -> 423662 | M23: =+L23-K23 -> 0
A25: (*) Promedio de litro de combustible utilizado en relación a kilometros recorridos.
A26: KILOMETRAJE INICIAL | E26: =+K9 -> 423200 | G26: FIRMA CONDUCTOR | I26: CONFORMIDAD INMEDIATO SUPERIOR | K26: CONFORMIDAD MAESTRANZA | M26: CONFORMIDAD ACTIVOS FIJOS | O26: CONFORMIDAD RESP. DE COMBUSTIBLE
A27: KILOMETRAJE FINAL | E27: =+L23 -> 423662
A28: KILOMETRAJE RECORRIDO | E28: =+E27-E26 -> 462
A29: COMBUSTIBLE CARGADO EN EL PERIODO | E29: =SUM(H9:H24) -> 79.76
A30: COMBUSTIBLE CONSUMIDO EN EL PERIODO | E30: =SUM(I9:I24) -> 92.4
A31: KILOMETRAJE POR LITRO GASOLINA | E31: 5
A32: LITROS SOBRANTES PARA EL MES SIGUIENTE | E32: =+J23 -> 65.76
A34: OBSERVACIONES:

Sheet EJEMPLO JMCC (6)
A1: REPORTE DE USO DE COMBUSTIBLE EN VEHíCULOS
A2: GESTION | C2: 2026 | K2: SECRETARIA : | M2: DESPACHO
A3: MES | C3: FEBRERO | K3: TIPO DE VEHICULO | M3: VAGONETA - TOYOTA
A4: CHOFER | C4: JOSE MANUEL CABEZAS | K4: PLACA | M4: 3772 ULS
A5: LUGAR | C5: POTOSI | K5: COLOR | M5: BLANCO
A6: FECHA | B6: Nº VALE | C6: CANT. | D6: OBJETO DE VIAJE O TRABAJO | H6: COMBUSTIBLE | K6: KILOMETRAJE | N6: RESPONSABLE DE VIAJE | P6: FIRMA
H7: INGRESO | I7: UTILIZADO (*) | J7: SALDO | K7: SALIDA | L7: LLEGADA | M7: RECORRIDO
D8: SALDO ANTERIOR | J8: =+'EJEMPLO JMCC (5)'!E32 -> 65.76 | L8: =+'EJEMPLO JMCC (5)'!E27 -> 423662
A9: 46069 | D9: APOYO LOCAL | H9: =C9 -> 0 | I9: =+M9/$E$31 -> 15.4 | J9: =+J8+H9-I9 -> 50.36 | K9: =+L8 -> 423662 | L9: =+L8+77 -> 423739 | M9: =+L9-K9 -> 77
A10: =+A9+1 -> 46070 | D10: APOYO LOCAL | H10: =C10 -> 0 | I10: =+M10/$E$31 -> 1 | J10: =+J9+H10-I10 -> 49.36 | K10: =+L9 -> 423739 | L10: =+L9+5 -> 423744 | M10: =+L10-K10 -> 5
A11: =+A10+1 -> 46071 | D11: APOYO LOCAL | H11: =C11 -> 0 | I11: =+M11/$E$31 -> 4 | J11: =+J10+H11-I11 -> 45.36 | K11: =+L10 -> 423744 | L11: =+L10+20 -> 423764 | M11: =+L11-K11 -> 20
